Workbook
Name CIĘCIE: OFFSET(TERMO!$R$33,0,0,ROWS(TERMO!$R$34:$R$40)-COUNTBLANK(TERMO!$R$34:$R$40),1)
Name Frez: OFFSET(FREZ!$F$36,0,0,COUNT(FREZ!$G$36:$G$52),1)
Name TERMO: OFFSET(TERMO!$R$34,0,0,ROWS(TERMO!$R$34:$R$40)-COUNTBLANK(TERMO!$R$34:$R$40),1)

Sheet KALKULATOR
A1: 0.00069444444 | B1: =VLOOKUP(F1,Tabela1[[Nazwa]:[indeks2]],32,FALSE) -> PŁVKBB-3,02,05x3,05 | C1: Materiał --> | E1: Nazwa | F1: Płyta VIVAK b/b 2050x3050 ≠3 | H1: Nakład elementu | I1: 100
A2: FALSE | B2: 0.041666667
J3: KOSZT | L3: CZAS
C4: Wymiary formatki | E4: ILOŚĆ UŻYTKÓW NA FORMATCE | F4: ILOŚĆ KOLORÓW | G4: ILOŚĆ PRZELOTÓW | H4: RODZAJ FARBY | J4: ="Dla przedstawionych parametrów korzystniejszy druk jest na "&DRUK!D78 -> Dla przedstawionych parametrów korzystniejszy druk jest na Atma | P4: Alternatywna maszyna | R4: =DRUK!D79 -> x
A5: TRUE | C5: dłuższa krawędź [mm] | D5: krótsza krawędź [mm] | J5: OPERACJA NAKŁAD | K5: PRZEZBROJENIE NAKŁAD | L5: OPERACJA NAKŁAD | M5: PRZEZBROJENIE NAKŁAD | N5: CZAS NA 1 SZTUKĘ | R5: OPERACJA NAKŁAD | S5: PRZEZBROJENIE NAKŁAD
C6: 1500 | D6: 1000 | E6: 1 | F6: 5 | G6: 5 | H6: srebrna | J6: =IF(A5=A2,0,DRUK!B81) -> 1822.0139 | K6: =IF(A5=A2,0,DRUK!B82) -> 1958.3333 | L6: =DRUK!B78 -> 0.2259838 | M6: =DRUK!B79 -> 0.17361111 | N6: =L6/$I$1 -> 0.002259838 | P6: =DRUK!D79 -> x | R6: =IF(P6="x","x",DRUK!F37) -> x | S6: =IF(P6="x","x",DRUK!F38) -> x
O8: DODATKOWE OPERACJE
C9: Wymiary formatki | E9: ILOSĆ UŻYTKÓW NA FORMATCE | F9: JAKOŚĆ WYDRUKU | J9: KOSZT | L9: CZAS | O9: MALOWANIE PRIMEREM
A10: TRUE | C10: dłuższa krawędź [mm] | D10: krótsza krawędź [mm] | J10: OPERACJA NAKŁAD | K10: PRZEZBROJENIE NAKŁAD | L10: OPERACJA NAKŁAD | M10: PRZEZBROJENIE NAKŁAD | N10: CZAS NA 1 SZTUKĘ | O10: OPERACJA NAKŁAD | P10: PRZEZBROJENIE NAKŁAD
C11: 600 | D11: 600 | E11: 1 | F11: Do podświetleń/wysoka jakość/bezbarwny | J11: =IF(A10=A2,0,DRUK!M10) -> 702.17102 | K11: =IF(A10=A2,0,DRUK!M11) -> 21.666667 | L11: =DRUK!L10 -> 0.16159328 | M11: =DRUK!L11 -> 0.0069444444 | N11: =L11/$I$1 -> 0.0016159328 | O11: x | P11: x
C13: Wymiary formatki | E13: ILOSĆ UŻYTKÓW NA FORMATCE | J13: KOSZT | L13: CZAS
A14: TRUE | C14: szerokość (druk z roli) [mm] | D14: długość (druk z roli) [mm] | J14: OPERACJA NAKŁAD | K14: PRZEZBROJENIE NAKŁAD | L14: OPERACJA NAKŁAD | M14: PRZEZBROJENIE NAKŁAD | N14: CZAS NA 1 SZTUKĘ
C15: 1400 | D15: 1000 | E15: 5 | J15: =IF(A2=A14,0,DRUK!M38) -> 690.47333 | K15: =IF(A2=A14,0,DRUK!M39) -> 16.25 | L15: =DRUK!L38 -> 0.44261111 | M15: =DRUK!L39 -> 0.010416667 | N15: =L15/$I$1 -> 0.0044261111
J17: KOSZT | L17: CZAS
A18: TRUE | C18: RODZAJ ELEMENTÓW | D18: ILOSĆ UŻYTKÓW NA FORMATCE | E18: ILOŚĆ MATRYC | J18: OPERACJA NAKŁAD | K18: PRZEZBROJENIE NAKŁAD | L18: OPERACJA NAKŁAD | M18: PRZEZBROJENIE NAKŁAD | N18: CZAS NA 1 SZTUKĘ
C19: CZÓŁKA DO TREI itp.. | D19: 1 | E19: 3 | J19: =IF(A2=A18,0,DRUK!M62) -> 58.444444 | K19: =IF(A2=A18,0,DRUK!M63) -> 186.66667 | L19: =DRUK!L62 -> 0.024189815 | M19: =DRUK!L63 -> 0.097222222 | N19: =L19/$I$1 -> 0.00024189815
O21: Dodatkowe operacje
J22: KOSZT | L22: CZAS | O22: Docinanie po laminowaniu
A23: TRUE | C23: WIELKOŚĆ FORMATKI | D23: ILOSĆ UŻYTKÓW NA FORMATCE | E23: FORMATOWANIE PO LAMINOWANIU | F23: DŁUGOŚĆ DOCINANIA [mm] | J23: OPERACJA NAKŁAD | K23: PRZEZBROJENIE NAKŁAD | L23: OPERACJA NAKŁAD | M23: PRZEZBROJENIE NAKŁAD | N23: CZAS NA 1 SZTUKĘ | O23: OPERACJA NAKŁAD | P23: PRZEZBROJENIE NAKŁAD
C24: B2 | D24: 1 | E24: Z FORMATOWANIEM | F24: 130 | J24: =IF(A2=A23,0,DRUK!M87+DRUK!M89) -> 93.360075 | K24: =IF(A2=A23,0,DRUK!M88+DRUK!M90) -> 9 | L24: =DRUK!L87 -> 0.094492814 | M24: =DRUK!L88 -> 0.0069444444 | N24: =L24/$I$1 -> 0.00094492814 | O24: =DRUK!L89 -> 0.015335648 | P24: =DRUK!L90 -> 0.0034722222
C27: ILOSĆ NAKLEJEK NA FORMATCE | D27: DŁUGOŚĆ NAKLEJKI [mm] | E27: SZEROKOŚĆ NAKLEJKI [mm] | F27: Typ klejenia | J27: KOSZT | L27: CZAS
A28: TRUE | C28: 1 | D28: 600 | E28: 300 | F28: Na mokro | J28: OPERACJA NAKŁAD | K28: PRZEZBROJENIE NAKŁAD | L28: OPERACJA NAKŁAD | M28: PRZEZBROJENIE NAKŁAD | N28: CZAS NA 1 SZTUKĘ
C29: Rodzaj elementu wyklejanego | D29: Typ docinania | E29: Długość docinania | F29: Typ naklejki | J29: =IF(A2=A28,0,DRUK!T12) -> 176.21078 | K29: =IF(A2=A28,0,DRUK!T13) -> 3.1666667 | L29: =DRUK!S12 -> 0.19321357 | M29: =DRUK!S13 -> 0.0034722222 | N29: =L29/$I$1 -> 0.0019321357
C30: Formatka | D30: linia, koło | E30: 130 | F30: folia-lustro (złoto), folia oracal
J32: KOSZT | L32: CZAS
A33: TRUE | C33: MATERIAŁ | D33: ZADRUKOWANE? | E33: ILOSĆ UŻYTKÓW NA FORMATCE | F33: ŁĄCZNA DŁUGOŚĆ ŚCIEŻEK [MM] | J33: OPERACJA NAKŁAD | K33: PRZEZBROJENIE NAKŁAD | L33: OPERACJA NAKŁAD | M33: PRZEZBROJENIE NAKŁAD | N33: CZAS NA 1 SZTUKĘ
C34: FOLIA | D34: Z DRUKIEM | E34: 1 | F34: 1500 | J34: =IF(A2=A33,0,DRUK!T39) -> 100 | K34: =IF(A2=A33,0,DRUK!T40) -> 20 | L34: =DRUK!S39 -> 0.069444444 | M34: =DRUK!S40 -> 0.013888889 | N34: =L34/$I$1 -> 0.00069444444
O38: Dodatkowe operacje
J39: KOSZT | L39: CZAS | O39: WYRYWANIE
C40: WIELKOŚĆ FORMATKI | D40: ILOSĆ UŻYTKÓW NA FORMATCE | E40: ILOŚĆ Z WYKROJNIKA | J40: OPERACJA NAKŁAD | K40: PRZEZBROJENIE NAKŁAD | L40: OPERACJA NAKŁAD | M40: PRZEZBROJENIE NAKŁAD | N40: CZAS NA 1 SZTUKĘ | O40: OPERACJA NAKŁAD | P40: PRZEZBROJENIE NAKŁAD
A41: TRUE | C41: B0+ | D41: 1 | E41: 1 | J41: =IF(A2=A41,0,INTRO!G14+INTRO!G16) -> 189.33333 | K41: =IF(A2=A41,0,INTRO!G15+INTRO!G17) -> 56.333333 | L41: =INTRO!F14 -> 0.020833333 | M41: =INTRO!F15 -> 0.020833333 | N41: =L41/$I$1 -> 0.00020833333 | O41: =INTRO!F16 -> 0.15277778 | P41: =INTRO!F17 -> 0.0069444444
C42: Wyrywanie | D42: RODZAJ FORMATKI | E42: ILOŚĆ UŻYTKÓW DO WYRWANIA
C43: TAK | D43: Błona | E43: 30
J45: KOSZT | L45: CZAS
C46: WIELKOŚĆ FORMATKI | D46: ILOSĆ UŻYTKÓW NA FORMATCE | J46: OPERACJA NAKŁAD | K46: PRZEZBROJENIE NAKŁAD | L46: OPERACJA NAKŁAD | M46: PRZEZBROJENIE NAKŁAD | N46: CZAS NA 1 SZTUKĘ
A47: TRUE | C47: B0 | D47: 1 | J47: =IF(A2=A47,0,INTRO!N9) -> 25.972222 | K47: =IF(A2=A47,0,INTRO!N10) -> 27.5 | L47: =INTRO!M9 -> 0.019675926 | M47: =INTRO!M10 -> 0.020833333 | N47: =L47/$I$1 -> 0.00019675926
J49: KOSZT | L49: CZAS
C50: NA ILE POCIĄĆ? | D50: ILOSĆ UŻYTKÓW NA FORMATCE | E50: RODZAJ MATERIAŁU | J50: OPERACJA NAKŁAD | K50: PRZEZBROJENIE NAKŁAD | L50: OPERACJA NAKŁAD | M50: PRZEZBROJENIE NAKŁAD | N50: CZAS NA 1 SZTUKĘ
A51: TRUE | C51: 10 | D51: 2 | E51: Kaszerowany | J51: =IF(A2=A51,0,INTRO!X17) -> #VALUE! | K51: =IF(A2=A51,0,INTRO!X18) -> 13.75 | L51: =INTRO!W17 -> #VALUE! | M51: =INTRO!W18 -> 0.010416667 | N51: =L51/$I$1 -> #VALUE!
J53: KOSZT | L53: CZAS
...

Sheet DRUK
A1: 0.00069444444 | B1: 0.041666667 | V1: TAK
G2: UV | N2: WYKLEJANIE RĘCZNE | V2: NIE
A3: Wymiary formatki | B3: =KALKULATOR!C6 -> 1500 | C3: =KALKULATOR!D6 -> 1000 | D3: =B3*C3/1000000 -> 1.5 | G3: =KALKULATOR!C11 -> 600 | H3: =KALKULATOR!D11 -> 600 | I3: =G3*H3/1000000 -> 0.36 | K3: Ploter Aquity | L3: koszt maszyna | M3: =VLOOKUP(K3,Tabela13[[Maszyna]:[Stawka]],2,FALSE) -> 130 | N3: ILOŚĆ NAKLEJEK | O3: =KALKULATOR!I1/KALKULATOR!C28 -> 100 | S3: koszt maszyny | T3: 38
A4: Ilość formatek do druku | B4: =KALKULATOR!I1/KALKULATOR!E6 -> 100 | E4: koszt [m^2] - 1 kolor | G4: Ilość formatek | H4: =KALKULATOR!I1/KALKULATOR!E11 -> 100 | L4: operacja reczna | M4: 38 | N4: DŁUGOŚĆ NAKLEJKI [mm] | O4: =KALKULATOR!D28 -> 600
A5: Materiał | B5: =VLOOKUP(KALKULATOR!B1,Materiały_zakupowe!A:AC,17,FALSE) -> inne | D5: Pokrycie - farba | E5: zwykła | F5: srebrna | G5: =VLOOKUP(H3,$J$13:$M$16,MATCH(G3,J13:M13,1),TRUE) -> do b1 | N5: SZEROKOŚĆ NAKLEJKI [mm] | O5: =KALKULATOR!E28 -> 300
D6: 2 | E6: 0.68 | F6: 1.2 | G6: Primer | L6: Powierzchnia nakładu | M6: =I3*H4 -> 36 | N6: Typ klejenia | O6: =KALKULATOR!F28 -> Na mokro
A7: =B5&VLOOKUP(C3,$A$15:$C$17,MATCH(B3,A15:C15,1),TRUE) -> innePowyżej B0 | E7: HDF SUROWA | F7: 6 | L7: koszt farby | M7: 5.5 | N7: Rodzaj elementu wyklejanego | O7: =KALKULATOR!C30 -> Formatka
E8: koszt [m^2] | F8: =IF(D13="TAK",F7,HLOOKUP(KALKULATOR!H6,DRUK!E5:F6,2,FALSE)) -> 1.2 | G8: Do podświetleń/wysoka jakość/bezbarwny | H8: 4.6 | L8: koszt farby nakład | M8: =M7*M6 -> 198 | N8: Typ docinania | O8: =KALKULATOR!D30 -> linia, koło
A9: Materiał&Powierzchnia | B9: maszyna | G9: Inne | H9: 8.25 | N9: Długość docinania | O9: =KALKULATOR!E30 -> 130
A10: DrewnoDo B0 | B10: Insignia | E10: Powierzchnia nakładu | F10: =D3*B4 -> 150 | K10: Druk | L10: =IF(AND(H4>25,MIN(G3:H3)>=600),L21*H4,IF(OR(G3="",H3="",H4=""),"",((H22+H23+VLOOKUP(G5,G19:J21,3,FALSE)*L25)+VLOOKUP(G5,G19:J21,2,FALSE))*IF(H4<L25,1,ROUNDDOWN(H4/L25,0)))) -> 0.16159328 | M10: =(L10*$M$3*24)+M8 -> 702.17102 | N10: Typ naklejki | O10: =KALKULATOR!F30 -> folia-lustro (złoto), folia oracal
A11: DrewnoPowyżej B0 | B11: Atma | K11: Przezbrojenei | L11: 0.0069444444 | M11: =L11*$M$3*24 -> 21.666667
A12: InneDo B0 | B12: Insignia | D12: Czy HDF surowa | F12: zwykła | G12: Maksymalna pow zadruku stare UV | Q12: Operacja | R12: =SUM(Q24:R24) -> 0.0019321357 | S12: =SUM(Q24:R24)*O3 -> 0.19321357 | T12: =S12*24*$T$3 -> 176.21078
A13: InnePowyżej B0 | B13: Atma | D13: =IF(AND(ISNUMBER(SEARCH("HDF",KALKULATOR!F1,1)),ISNUMBER(SEARCH("surowa",KALKULATOR!F1,1))),"TAK","NIE") -> NIE | F13: srebrna | G13: 2500 | K13: 1 | L13: 1001 | M13: 1401 | N13: =(O4*O5)/(1000^2) -> 0.18 | Q13: Przezbrojenei | S13: 0.0034722222 | T13: =S13*24*$T$3 -> 3.1666667
G14: 1200 | J14: 1 | K14: do b1 | L14: do b0 | M14: powyżej b0
B15: 1 | C15: 1401 | J15: 701 | K15: do b0 | L15: do b0 | M15: powyżej b0 | N15: linia, koło | O15: 1 | P15: formatka | Q15: 1
A16: 1 | B16: Do B0 | C16: Powyżej B0 | J16: 1001 | K16: do b0 | L16: powyżej b0 | M16: powyżej b0 | N16: kształt | O16: 1.5 | P16: wytłoczka | Q16: 1.5
A17: 1001 | B17: Powyżej B0 | C17: Powyżej B0 | N17: Na sucho | O17: 1 | P17: naklejka | Q17: 1 | R17: 0 | S17: 0.00028935185
G18: Wielkość formatki | H18: Dojazd | I18: Wymiana | J18: Wymiana + dojazd | N18: Na mokro | O18: 1.33 | P18: folia-lustro (złoto), folia oracal | Q18: 1.33 | R18: 0.0025 | S18: 0.0016589506
G19: powyżej B0 | H19: 0.00052083333 | I19: 0.00052083333 | J19: 0.0010416667 | P19: folia szron | Q19: 2 | R19: 0.0225 | S19: 0.001009838
G20: do B0 | H20: 0.00052083333 | I20: 0.00034722222 | J20: 0.00086805556 | R20: 0.5 | S20: 0.00026909722
A21: Atma | G21: do B1 | H21: 0.00052083333 | I21: 0.00023148148 | J21: 0.00075231481 | L21: =((SUM(P62:P64)-P63*(2-L25))/L25+SUM(P59:P60))*(1+P61) -> 0.0016159328 | N21: czas wyklejanie | O21: czas docinanie
A22: ilośc kolorów | B22: =KALKULATOR!F6 -> 5 | C22: 0.00069444444 | D22: Atma | E22: Koszt maszyny | F22: =VLOOKUP(D22,Tabela13[[Maszyna]:[Stawka]],2,FALSE) -> 170 | G22: Czas druku | H22: =I25/H26 -> 0.0018077957
A23: ilość przelotów | B23: =KALKULATOR!G6 -> 5 | C23: 8000 | E23: Koszt farby | F23: =F10*F8*B22 -> 900 | G23: Czas zmiany pasów | H23: =H27*H25 -> 0.0052185036 | N23: 2.3148148e-05 | Q23: czas wyklejanie | R23: czas docinanie
A24: Dł rakla | B24: =MAX(B3:C3) -> 1500 | C24: 4000 | D24: TRUDNE PASOWANIA NAKŁADY DO 100szt. | E24: Koszt siatki | F24: 250 | Q24: =VLOOKUP(N13,R17:S20,2,TRUE)*VLOOKUP(O6,N17:O18,2,FALSE)*VLOOKUP(O10,P17:Q19,2,FALSE)*VLOOKUP(O7,P15:Q16,2,FALSE) -> 0.0017863024 | R24: =IF(O9>0,O9/100*N23*VLOOKUP(O8,N15:O16,2,FALSE)+10/24/60/60,0) -> 0.00014583333
A25: Ilość formatek do druku | B25: =KALKULATOR!I1/KALKULATOR!E6 -> 100 | C25: =IF(B25<=150,C24,C23) -> 4000 | G25: ilość pasów | H25: =ROUNDUP((H3/VLOOKUP(KALKULATOR!F11,DRUK!G8:H9,2,FALSE)+4)*2,0) -> 269 | I25: =H25*G3 -> 161400 | K25: liczba formatek na stole | L25: =IF(H4>25,IF(AND(MAX(G3:H3)<=MAX(G13:G14),MIN(G3:H3)<=MIN(G13:G14),MIN(G3:H3)>=600),2,1),1) -> 2
A26: =VLOOKUP(C3,$A$15:$C$17,MATCH(B3,$A$15:$C$15,1),TRUE) -> Powyżej B0 | G26: predkosc | H26: =I26/A1*I27 -> 89280000 | I26: 62
G27: czas zmiany poziomu | H27: =(H28+H29)/H26+I29 -> 1.9399642e-05 | I27: 1000
A28: druk | C28: przezbrojenie | G28: szerokość głowicy + zapas na pas | H28: 855
A29: czas rakla | B29: =B24/C25*C22 -> 0.00026041667 | C29: =IF(A26=E29,F29,F30) -> 0.020833333 | E29: do B0 | F29: 0.010416667 | H29: 40 | I29: 9.375e-06
A30: NAJAZD I POWRÓT STOŁU | B30: 9.2592593e-05 | C30: 0.0069444444 | D30: zatowarowanie | E30: powyżej B0 | F30: 0.020833333
A31: ODBIERANIE FORMATEK | B31: 5.787037e-05 | C31: =F32*B22-F31 -> 0.14236111 | F31: 0.013888889
A32: Czas 1 formatki dla 1 kolor | B32: =SUM(B29:B31) -> 0.00041087963 | C32: 0.0034722222 | F32: 0.03125 | G32: SOLWENT | N32: PLOTER TNĄCY ROLAND
C33: =SUM(C28:C32) -> 0.17361111 | D33: czas przezbrojenia | G33: dł | H33: =KALKULATOR!C15+20 -> 1420 | I33: Papier, Folia | J33: 7000 | K33: Ploter Roland 1 | L33: Koszt maszyny | M33: =VLOOKUP(K33,Tabela13[[Maszyna]:[Stawka]],2,FALSE) -> 65 | N33: MATERIAŁ | O33: =KALKULATOR!C34 -> FOLIA | R33: Ploter Tnący – M | S33: Koszt maszyny | T33: =VLOOKUP(DRUK!R33,Tabela13[[Maszyna]:[Stawka]],2,FALSE) -> 60
G34: szer | H34: =KALKULATOR!D15+20 -> 1020 | I34: Backlite | J34: 3000 | N34: druk | O34: =KALKULATOR!D34 -> Z DRUKIEM
G35: Materiał | H35: backlite | N35: ilosc formatek | O35: =KALKULATOR!I1/KALKULATOR!E34 -> 100
A36: Czas druku | G36: ilość formatek | H36: =KALKULATOR!I1/KALKULATOR!E15 -> 20 | I36: 0.013888889 | N36: ilosc użytków | O36: =KALKULATOR!E34 -> 1
B37: Ilość przelotów | E37: Czas druku | F37: =IF(B22<=B23,C51*1.1,C51*1.1/0) -> 0.2259838 | N37: długość cięcia | O37: =KALKULATOR!F34 -> 1500
A38: 1 KOLOR | B38: =IF($B$23>=1,1,0) -> 1 | C38: =B38*$B$25*$B$32 -> 0.041087963 | E38: Czas przezbrojenia | F38: =IF(B22<=B23,C33,C33/0) -> 0.17361111 | G38: druk | H38: =H33*H34/1000000*B1/(VLOOKUP(H35,I33:J34,2,FALSE)/1000)*H36 -> 0.40233333 | K38: Druk | L38: =SUM(H38:H39) -> 0.44261111 | M38: =$M$33*24*L38 -> 690.47333
A39: 2 KOLOR | B39: =IF($B$23>=2,1,0) -> 1 | C39: =B39*$B$25*$B$32 -> 0.041087963 | G39: czyszczenie | H39: =I39*I36/10 -> 0.040277778 | I39: =ROUNDUP(H38/I36,0) -> 29 | K39: Przezbrojenei | L39: 0.010416667 | M39: =$M$33*24*L39 -> 16.25 | R39: Druk | S39: =O44*O35 -> 0.069444444 | T39: =S39*24*$T$33 -> 100
A40: 3 KOLOR | B40: =IF($B$23>=3,1,0) -> 1 | C40: =B40*$B$25*$B$32 -> 0.041087963 | E40: Koszt druku | F40: =(F37*24*F22)+F23 -> 1822.0139 | H40: =SUM(H38:H39) -> 0.44261111 | N40: prędkość | O40: =VLOOKUP(O33,N48:P49,MATCH(O34,N47:P47,0),FALSE) -> 50 | P40: 1.1574074e-05 | R40: Przezbrojenei | S40: =VLOOKUP(O34,R48:S49,2,FALSE) -> 0.013888889 | T40: =S40*24*$T$33 -> 20
...

Sheet INTRO
A1: 0.00069444444 | B1: 0.041666667 | C1: TAK | D1: NIE
A2: SZTANCOWANIE | H2: KASZEROWANIE | O2: GILOTYNA- CIĘCIE
A3: WIELKOŚĆ FORMATKI | B3: =KALKULATOR!C41 -> B0+ | F3: Koszt maszyny | G3: 100 | H3: WIELKOŚĆ FORMATKI | I3: =KALKULATOR!C47 -> B0 | L3: Kaszerka K | M3: Koszt maszyny | N3: =VLOOKUP(L3,Tabela13[[Maszyna]:[Stawka]],2,FALSE) -> 55 | O3: ilość użytków | P3: =KALKULATOR!C51 -> 10 | S3: Gilotyna G1 | T3: Stawka maszyny | U3: =VLOOKUP(S3,Tabela13[[Maszyna]:[Stawka]],2,FALSE) -> 55
A4: ILOŚĆ FORMATEK | B4: =KALKULATOR!I1/KALKULATOR!D41 -> 100 | F4: Wyklejanie | G4: 38 | H4: ILOŚĆ FORMATEK | I4: =KALKULATOR!I1/KALKULATOR!D47 -> 100 | O4: Ilość formatek | P4: =KALKULATOR!I1/KALKULATOR!D51 -> 50
A5: ILOŚĆ UŻYTKÓW NA FORMATCE | B5: =KALKULATOR!D41 -> 1 | H5: Materiał | I5: =VLOOKUP(KALKULATOR!B1,Materiały_zakupowe!A:AC,14,FALSE) -> Tworzywo | O5: RODZAJ MATERIAŁU | P5: =KALKULATOR!E51 -> Kaszerowany | T5: Druk Offset | U5: 9 | AB5: ILOŚĆ PŁYT PO CIĘCIU | AC5: ILOŚĆ CIĘĆ
A6: ILOŚĆ Z WYKROJNIKA | B6: =KALKULATOR!E41 -> 1 | O6: Grubość | P6: =VLOOKUP(KALKULATOR!B1,Materiały_zakupowe!A:U,21,FALSE) -> 3 | T6: Druk Sito | U6: 10 | Y6: 0 | Z6: 1 | AB6: 2 | AC6: 1
A7: Wyrywanie | B7: =KALKULATOR!C43 -> TAK | O7: Materiał do kalkulatora | P7: =VLOOKUP(KALKULATOR!B1,Materiały_zakupowe!A:X,VLOOKUP(INTRO!P5,T5:U8,2,FALSE),FALSE) -> KASZEROWANY | T7: Kaszerowany | U7: 11 | Y7: 51 | Z7: 0.8 | AB7: 4 | AC7: 2
A8: RODZAJ FORMATKI | B8: =KALKULATOR!D43 -> Błona | H8: =IF(I3=H17,1,IF(I3=H18,2,IF(I3=H19,3,IF(I3=H20,4,IF(I3=H21,5,0))))) -> 2 | I8: =IF(I5=I16,1,IF(I5=J16,2,IF(I5=K16,3,IF(I5=L16,4,IF(I5=M16,5,IF(I5=N16,6,0)))))) -> 6 | O8: Ilość w pakiecie | P8: =VLOOKUP(P6,O21:AE30,MATCH(P7,O21:AE21,0),FALSE) -> X | T8: Pozostałe | U8: 12 | Y8: 101 | Z8: 0.6 | AB8: 8 | AC8: 3
A9: ILOŚĆ UŻYTKÓW DO WYRWANIA | B9: =KALKULATOR!E43 -> 30 | L9: Operacja | M9: =H10*I4 -> 0.019675926 | N9: =M9*24*$N$3 -> 25.972222 | O9: Ilość pakietów | P9: =ROUNDUP(P4/P8,0) -> #VALUE! | R9: 0.0034722222 | Y9: 151 | Z9: 0.5 | AB9: 16 | AC9: 4
A10: Grubość | B10: =IF(VLOOKUP(KALKULATOR!F1,Tabela1[[Nazwa]:[GRUBOŚĆ]],20,FALSE)>1,G37,F37) -> Powyżej 1mm | H10: =INDEX(I17:N21,H8,I8) -> 0.00019675926 | L10: Przezbrojenei | M10: 0.020833333 | N10: =M10*24*$N$3 -> 27.5 | O10: ilośc płyt zakładana na raz | P10: 5 | Y10: 201 | Z10: 0.4 | AB10: 32 | AC10: 5
A11: Materiał | B11: =VLOOKUP(KALKULATOR!F1,Tabela1[[Nazwa]:[SZTANCOWANIE wyr tworz]],17,FALSE) -> Tworzywo | Y11: 301 | Z11: 0.3 | AB11: 64 | AC11: 6
AB12: 128 | AC12: 7
A13: B0+ | B13: 0.00020833333 | C13: Powyżej B0 | O13: czas założenia 1 pakietu płyt | P13: 0.00017361111 | Q13: =P13*ROUNDUP(P4/P10,0) -> 0.0017361111 | T13: =MATCH(P7,P21:AE21,0) -> 5 | V13: nr wiersza do wspo | W13: nr kolumny do wsp | AB13: 256 | AC13: 8
A14: B0 | B14: 0.00017361111 | C14: do B0 | D14: Tygiel | E14: Operacja | F14: =VLOOKUP(B3,A13:B18,2,FALSE)*B4*ROUNDUP(B5/B6,0) -> 0.020833333 | G14: =F14*24*$G$3 -> 50 | O14: czas 1 cięcia | Q14: =HLOOKUP(P7,O21:AE31,11,FALSE)*INDEX(AB19:AC20,V14,W14)*T15*IF(P8>P4,1,VLOOKUP(P3,Y6:Z11,2,TRUE))*P9 -> #VALUE! | T14: =POWER(2,VLOOKUP(P8,AB6:AC15,2,TRUE)) -> #N/A | V14: =IF(P3<=4,1,IF(P3>4,2)) -> 2 | W14: =IF(T13<=6,2,1) -> 2 | AB14: 512 | AC14: 9
A15: B1 | B15: 0.00016203704 | C15: do B1 | E15: Przezbrojenei | F15: =A20+(A21*(B5/B6-1)) -> 0.020833333 | G15: =F15*24*$G$3 -> 50 | O15: czas zdejmowania użytków | P15: 0.00017361111 | Q15: =P15*P9*T15*VLOOKUP(P3,Y6:Z11,2,TRUE) -> #VALUE! | T15: =ROUNDUP(IF(AND(P4<P8,T13>6),P3/T14,P3),0) -> 10 | AB15: 1024 | AC15: 10
A16: B2 | B16: 0.00013888889 | C16: do B1 | D16: Wyrywanie | E16: Operacja | F16: =IF(B11="Tworzywo",G34,F34) -> 0.15277778 | G16: =F16*24*$G$4 -> 139.33333 | H16: FORMAT | I16: T. LITA | J16: T. LITA #1,5 | K16: T. FALA [E] | L16: T. FALA [B] | M16: T. FALA [EB] | N16: TWORZYWO | Q16: =SUM(Q13:Q15) -> #VALUE!
A17: B3 | B17: 0.00010416667 | C17: do B1 | E17: Przezbrojenei | F17: =IF(B7="nie",0,A24) -> 0.0069444444 | G17: =F17*24*$G$4 -> 6.3333333 | H17: B0+ | I17: X | J17: X | K17: 0.00011574074 | L17: 0.00011574074 | M17: 0.00012731481 | N17: 0.00025462963 | V17: Operacja | W17: =IF(Q16<R9,R9,Q16) -> #VALUE! | X17: =W17*24*$U$3 -> #VALUE!
A18: B4 | B18: 9.2592593e-05 | C18: do B1 | H18: B0 | I18: 0.00011574074 | J18: 0.00011574074 | K18: 0.00011574074 | L18: 0.00011574074 | M18: 0.00012731481 | N18: 0.00019675926 | V18: Przezbrojenei | W18: 0.010416667 | X18: =W18*24*$U$3 -> 13.75 | AB18: NA TERMO, SZTANCOWANIE | AC18: KROJENIE-DRUK
H19: B1 | I19: 6.9444444e-05 | J19: 6.9444444e-05 | K19: 8.1018519e-05 | L19: 8.1018519e-05 | M19: 9.2592593e-05 | N19: 0.00017361111 | AA19: DO 4 UŻ/FORM. | AB19: 1 | AC19: 4
A20: 0.020833333 | H20: B2 | I20: 5.787037e-05 | J20: 5.787037e-05 | K20: 5.787037e-05 | L20: 5.787037e-05 | M20: 6.9444444e-05 | N20: 0.00016203704 | AA20: POWYŻEJ 4 UŻ/FORM. | AB20: 1 | AC20: 2.2
A21: 0.0069444444 | H21: B3 | I21: 8.1018519e-05 | J21: 8.1018519e-05 | K21: 8.1018519e-05 | L21: 8.1018519e-05 | M21: 8.1018519e-05 | N21: 0.00012731481 | O21: GRUBOŚĆ MATERIAŁU (MM) | P21: PCV Z DRUKIEM | Q21: HIPS Z DRUKIEM LUB LUSTRO | R21: DRUK OFF SET [≠0,2] | S21: DRUK SITO (folia, papier) [≠0,2] | T21: KASZEROWANY | U21: KODY, ETYKIETY, INSTRUKCJE itp. [#0,2] | V21: PCV | W21: HIPS | X21: VIVAK | Y21: TUPET /PET / AXPET | Z21: FOREX | AA21: TEKTURA LITA [≠2] | AB21: WYTŁOCZKI I POJEDYNCZE | AC21: TEKTURA FAL. [3W, 5W] | AD21: BACKLITE | AE21: DRUK OFF SET [≠0,5] GRUBA ALASKA
O22: 0.2 | P22: 30 | Q22: X | R22: 100 | S22: 50 | T22: X | U22: 100 | V22: 75 | W22: X | X22: X | Y22: X | Z22: X | AA22: X | AB22: 1 | AC22: X | AD22: 40 | AE22: x | AG22: =RIGHT(O22,LEN(O22)-1)*1 -> 0.2
A23: Wyrywanie | O23: 0.5 | P23: 20 | Q23: 20 | R23: X | S23: X | T23: 20 | U23: X | V23: 30 | W23: 50 | X23: 50 | Y23: 50 | Z23: X | AA23: X | AB23: 1 | AC23: X | AD23: x | AE23: 50 | AG23: =RIGHT(O23,LEN(O23)-1)*1 -> 0.5
A24: 0.0069444444 | E24: =VLOOKUP(B3,A13:C18,3,FALSE) -> Powyżej B0 | F24: do B1 | G24: 1 | O24: 0.8 | P24: 5 | Q24: 5 | R24: X | S24: X | T24: 5 | U24: X | V24: 30 | W24: 50 | X24: 50 | Y24: 30 | Z24: X | AA24: X | AB24: 1 | AC24: X | AD24: x | AE24: x | AG24: =RIGHT(O24,LEN(O24)-1)*1 -> 0.8
D25: Czas bezpieczeństwa na sprzątanie itp.- wyrywanie | E25: 0.1 | F25: do B0 | G25: 1.05 | O25: 1 | P25: 5 | Q25: 5 | R25: X | S25: X | T25: 5 | U25: X | V25: 20 | W25: 40 | X25: 30 | Y25: 15 | Z25: X | AA25: X | AB25: 1 | AC25: X | AD25: x | AE25: x | AG25: =RIGHT(O25,LEN(O25)-1)*1 -> #VALUE!
B26: do B1 | C26: do B0 | D26: powyżej B0 | F26: powyżej B0 | G26: 1.1 | O26: 1.5 | P26: 5 | Q26: 5 | R26: X | S26: X | T26: 5 | U26: X | V26: 15 | W26: 20 | X26: 30 | Y26: 15 | Z26: X | AA26: X | AB26: 1 | AC26: X | AD26: x | AE26: x | AG26: =RIGHT(O26,LEN(O26)-1)*1 -> 0.5
A27: Jednostronna grafika | B27: 6.9444444e-05 | C27: 8.1018519e-05 | D27: 9.2592593e-05 | O27: 2 | P27: X | Q27: 5 | R27: X | S27: X | T27: 5 | U27: X | V27: X | W27: 10 | X27: 20 | Y27: X | Z27: 35 | AA27: 40 | AB27: 1 | AC27: X | AD27: x | AE27: x | AG27: =RIGHT(O27,LEN(O27)-1)*1 -> #VALUE!
A28: Dwustronna grafika | B28: 9.2592593e-05 | C28: 0.00010416667 | D28: 0.00010416667 | O28: 3 | P28: X | Q28: X | R28: X | S28: X | T28: X | U28: X | V28: X | W28: X | X28: X | Y28: X | Z28: 25 | AA28: X | AB28: 1 | AC28: 25 | AD28: x | AE28: x | AG28: =RIGHT(O28,LEN(O28)-1)*1 -> #VALUE!
A29: Bez grafiki | B29: 3.4722222e-05 | C29: 4.6296296e-05 | D29: 5.787037e-05 | O29: 4 | P29: X | Q29: X | R29: X | S29: X | T29: X | U29: X | V29: X | W29: X | X29: X | Y29: X | Z29: 20 | AA29: X | AB29: 1 | AC29: X | AD29: x | AE29: x | AG29: =RIGHT(O29,LEN(O29)-1)*1 -> #VALUE!
A30: Błona | O30: 5 | P30: X | Q30: X | R30: X | S30: X | T30: X | U30: X | V30: X | W30: X | X30: X | Y30: X | Z30: 15 | AA30: X | AB30: 1 | AC30: 15 | AD30: x | AE30: x | AG30: =RIGHT(O30,LEN(O30)-1)*1 -> #VALUE!
A31: Błona + grafika | O31: czas i cięcia | P31: 0.00023148148 | Q31: 0.00023148148 | R31: 0.00017361111 | S31: 0.00017361111 | T31: 0.00023148148 | U31: 5.787037e-05 | V31: 0.00023148148 | W31: 0.00023148148 | X31: 0.00023148148 | Y31: 0.00023148148 | Z31: 0.00023148148 | AA31: 0.00023148148 | AB31: 0.00023148148 | AC31: 0.00023148148 | AD31: 0.00017361111 | AE31: 0.00017361111
A33: 0 | B33: 1 | F33: Czas dla kartonu | G33: Czas dla tworzywa
A34: 4 | B34: 0.8 | F34: =IF(B7="nie",0,VLOOKUP(B8,A26:D29,MATCH(E24,A26:D26,0),FALSE)*VLOOKUP(B9,A33:B37,2,TRUE)*(1+E25)*B4) -> #N/A | G34: =VLOOKUP($B$8,$E$37:$G$41,MATCH($B$10,$E$37:$G$37,0),FALSE)*B9*(ROUNDUP(B4/VLOOKUP(B8,A39:C43,MATCH(B10,A39:C39,0),FALSE),0)*VLOOKUP(E24,F24:G26,2,FALSE)) -> 0.15277778
A35: 7 | B35: 0.6
A36: 15 | B36: 0.3
A37: 30 | B37: 0.15 | F37: Do 1mm | G37: Powyżej 1mm
E38: Błona | F38: 3.4722222e-05 | G38: 4.6296296e-05
B39: Do 1mm | C39: Powyżej 1mm | E39: Jednostronna grafika | F39: 3.4722222e-05 | G39: 4.6296296e-05
A40: Błona | B40: 1 | C40: 1 | E40: Bez grafiki | F40: 0.00020833333 | G40: 0.00017361111
A41: Jednostronna grafika | B41: 1 | C41: 1 | E41: Błona + grafika | F41: 4.6296296e-05 | G41: 5.787037e-05
...

Sheet DREWNO
A1: Wiercenie | G1: Formatowanie- Holzma | M1: Ilość w stosie- Formatyzerka
A2: ILOŚĆ UŻYTKÓW (Detali) | B2: =KALKULATOR!C56 -> 1 | D2: Centrum BHX | E2: stawka maszyny | F2: =VLOOKUP(D2,Tabela13[[Maszyna]:[Stawka]],2,FALSE) -> 95 | G2: Materiał | H2: =VLOOKUP(KALKULATOR!B1,Materiały_zakupowe!A:AC,8,FALSE) -> Tupet, vivak, pcv | J2: Piła panelowa Holzma | K2: Koszt maszyny | L2: =VLOOKUP(J2,Tabela13[[Maszyna]:[Stawka]],2,FALSE) -> 100 | M2: Grubość | N2: PCV spienione | O2: Tupet, vivak, pcv | P2: DIBOND | Q2: Hips | R2: Plexa | S2: Płyta wiórowa, MDF sur. | T2: Płyta wiórowa, MDF lam. | U2: HDF sur. | V2: HDF lam. | W2: Sklejka | X2: Nadruk
A3: ILOŚĆ OTWORÓW | B3: =KALKULATOR!D56 -> 2 | G3: Grubość | H3: =VLOOKUP(KALKULATOR!B1,Materiały_zakupowe!A:AC,21,FALSE) -> 3 | M3: 1 | N3: x | O3: 6 | P3: 2 | Q3: 8 | R3: x | S3: x | T3: x | U3: x | V3: x | W3: 8 | X3: 1
A4: Ilość formatek | B4: =KALKULATOR!I1/KALKULATOR!C56 -> 100 | G4: Ilość formatek | H4: =KALKULATOR!I1/KALKULATOR!C65 -> 100 | M4: 1.5 | N4: x | O4: 6 | P4: 2 | Q4: 8 | R4: x | S4: x | T4: x | U4: x | V4: x | W4: 6 | X4: 1
D5: Operacja | E5: =SUM(A9:B9) -> 0.046296296 | F5: =E5*24*$F$2 -> 105.55556 | G5: NA ILE POCIĄĆ? | H5: =KALKULATOR!D65 -> 2 | M5: 2 | N5: 8 | O5: 6 | P5: 2 | Q5: 8 | R5: 8 | S5: x | T5: x | U5: x | V5: x | W5: 6 | X5: 1
D6: Przezbrojenei | E6: 0.013888889 | F6: =E6*24*$F$2 -> 31.666667 | G6: ilość w pakiecie | H6: =VLOOKUP(H3,M2:X19,MATCH(H2,M2:X2,0),FALSE) -> 4 | J6: Operacja | K6: =SUM(H10:H13) -> 0.083912037 | L6: =K6*24*$L$2 -> 201.38889 | M6: 3 | N6: 6 | O6: 4 | P6: 2 | Q6: 6 | R6: 4 | S6: x | T6: x | U6: 8 | V6: 4 | W6: 6 | X6: 1
A7: czas na 1 otwór | B7: zał+ zdjecie formatki | G7: Ilość pakietów | H7: =ROUNDUP(H4/H6,0) -> 25 | J7: Przezbrojenei | K7: 0.0069444444 | L7: =K7*24*$L$2 -> 16.666667 | M7: 4 | N7: 4 | O7: 2 | P7: 1 | Q7: 4 | R7: 4 | S7: x | T7: x | U7: x | V7: x | W7: 4 | X7: 1
A8: 5.787037e-05 | B8: 0.00034722222 | M8: 5 | N8: 3 | O8: x | P8: x | Q8: x | R8: 2 | S8: x | T8: x | U8: x | V8: x | W8: 4 | X8: 1
A9: =A8*B3*B4 -> 0.011574074 | B9: =B8*B4 -> 0.034722222 | M9: 6 | N9: 3 | O9: x | P9: x | Q9: x | R9: 2 | S9: 5 | T9: 4 | U9: 5 | V9: 2 | W9: 4 | X9: 1
G10: Czas cięcia elementu | H10: =VLOOKUP(HLOOKUP(H2,N2:X21,20,FALSE),J10:L12,2,FALSE)*VLOOKUP(H5,G15:I18,3,TRUE)*H7*H5 -> 0.028935185 | J10: B | K10: 0.0005787037 | L10: 0.00011574074 | M10: 8 | N10: 2 | O10: x | P10: x | Q10: x | R10: 2 | S10: 4 | T10: 3 | U10: x | V10: x | W10: 3 | X10: 1
G11: Czas podania płyty | H11: =I11*H4 -> 0.034722222 | I11: 0.00034722222 | J11: A | K11: 0.0005787037 | L11: 0.00023148148 | M11: 10 | N11: 2 | O11: x | P11: x | Q11: x | R11: 1 | S11: 3 | T11: 2 | U11: x | V11: x | W11: 2 | X11: 1
G12: Czas zdjęcia elementu | H12: =VLOOKUP(HLOOKUP(H2,N2:X21,20,FALSE),J10:L12,3,FALSE)*H5*H7 -> 0.011574074 | J12: NADRUK | K12: 0.00069444444 | L12: 0.00023148148 | M12: 12 | N12: 2 | O12: x | P12: x | Q12: x | R12: 1 | S12: 3 | T12: 2 | U12: x | V12: x | W12: 2 | X12: 1
H13: =I11*H7 -> 0.0086805556 | M13: 16 | N13: 2 | O13: x | P13: x | Q13: x | R13: 1 | S13: 2 | T13: 2 | U13: x | V13: x | W13: 2 | X13: 1
M14: 18 | N14: 1 | O14: x | P14: x | Q14: x | R14: 1 | S14: 2 | T14: 2 | U14: x | V14: x | W14: 2 | X14: 1
A15: Wiercenie-wielowrzecionówka | G15: 0 | H15: 10 | I15: 1 | M15: 19 | N15: 1 | O15: x | P15: x | Q15: x | R15: 1 | S15: 2 | T15: 2 | U15: x | V15: x | W15: 2 | X15: 1
A16: ILOŚĆ FORMATEK | B16: =KALKULATOR!I1/KALKULATOR!C60 -> 100 | D16: Wiertarka Wielowrzecionowa | E16: Koszt maszyny | F16: =VLOOKUP(D16,Tabela13[[Maszyna]:[Stawka]],2,FALSE) -> 70 | G16: 11 | H16: 20 | I16: 0.85 | M16: 22 | N16: 1 | O16: x | P16: x | Q16: x | R16: 1 | S16: 2 | T16: 2 | U16: x | V16: x | W16: 1 | X16: 1
A17: ILOŚĆ OTWORÓW | B17: =KALKULATOR!D60 -> 1 | G17: 21 | H17: 40 | I17: 0.7 | M17: 25 | N17: 1 | O17: x | P17: x | Q17: x | R17: 1 | S17: 1 | T17: 1 | U17: x | V17: x | W17: 1 | X17: 1
A18: ILOŚĆ PRZELOTÓW | B18: =KALKULATOR!E60 -> 1 | E18: 0.0069444444 | G18: 41 | I18: 0.5 | M18: 30 | N18: 1 | O18: x | P18: x | Q18: x | R18: 1 | S18: 1 | T18: 1 | U18: x | V18: x | W18: 1 | X18: 1
M19: 35 | N19: 1 | O19: x | P19: x | Q19: x | R19: 1 | S19: 1 | T19: 1 | U19: x | V19: x | W19: 1 | X19: 1
A20: Produkcja | N20: NIE LAMINOWANE | O20: NIE LAMINOWANE | P20: NIE LAMINOWANE | Q20: NIE LAMINOWANE | R20: NIE LAMINOWANE | S20: NIE LAMINOWANE | T20: LAMINOWANE | U20: NIE LAMINOWANE | V20: LAMINOWANE | W20: NIE LAMINOWANE | X20: NADRUK
A21: założenie+odłożenie | B21: 0.00017361111 | C21: =B18*B21 -> 0.00017361111 | N21: A | O21: A | P21: A | Q21: A | R21: A | S21: B | T21: B | U21: B | V21: B | W21: B | X21: NADRUK
A22: wiercenie | B22: 4.6296296e-05 | C22: =B18*B22 -> 4.6296296e-05
A23: odmuchanie | B23: 0.00011574074 | C23: =B17*B23 -> 0.00011574074
N24: 1*10*4
D25: Operacja | E25: =SUM(C21:C24)*B16 -> 0.033564815 | F25: =E25*24*$F$16 -> 56.388889
D26: Przezbrojenei | E26: =IF(SUM(C28:C29)<E18,E18,SUM(C28:C29)) -> 0.0069444444 | F26: =E26*24*$F$16 -> 11.666667 | G26: Oklejanie prostoliniowe
G27: Ilość formatek | H27: =KALKULATOR!I1/KALKULATOR!C70 -> 100 | J27: Okleiniarka Brandt | K27: stawka maszyny | L27: =VLOOKUP(DREWNO!J27,Tabela13[[Maszyna]:[Stawka]],2,FALSE) -> 100
A28: na otwór | B28: 0.00069444444 | C28: =B28*B17 -> 0.00069444444 | G28: Długość oklejania [mm] | H28: =KALKULATOR!D70 -> 8000
A29: na przelot | B29: 0.0013888889 | C29: =B29*B18 -> 0.0013888889 | J29: Operacja | K29: =(H28+H31)/H30*H32*H27 -> 0.11111111 | L29: =K29*24*$L$27 -> 266.66667
G30: predkosc | H30: 10000 | J30: Przezbrojenei | K30: 0.013888889 | L30: =K30*24*$L$27 -> 33.333333
G31: suchy przelot | H31: 8000
H32: 0.00069444444
A36: FREZOWANIE CENTRUM | G36: Oklejanie krzywoliniowe
A37: ILOŚĆ UŻYTKÓW (Detali) | B37: =KALKULATOR!D81 -> 1 | D37: Centrum obróbcze Homag | E37: stawka maszyn | F37: =VLOOKUP(D37,Tabela13[[Maszyna]:[Stawka]],2,FALSE) -> 85 | G37: ilość formatek | H37: =KALKULATOR!I1/KALKULATOR!C76 -> 100 | J37: Centrum obróbcze Homag | K37: Stawka maszyny | L37: =VLOOKUP(DREWNO!J37,Tabela13[[Maszyna]:[Stawka]],2,FALSE) -> 85
A38: ilość formatek | B38: =KALKULATOR!I1/KALKULATOR!D81 -> 100 | G38: DŁUGOŚĆ OKLEJANIA [MM] | H38: =KALKULATOR!D76 -> 2300
A39: Łączna długość ścieżek [mm] | B39: =KALKULATOR!E81 -> 1500 | G39: ILOŚĆ KRAWĘDZI | H39: =KALKULATOR!E76 -> 1
A40: Materiał | B40: =VLOOKUP(KALKULATOR!B1,Materiały_zakupowe!A:AC,23,FALSE) -> 0 | C40: do dodania w pozniejszym czasie (po aktualizacji kalkulatora redmine)
A41: Wielkość formatki | B41: =KALKULATOR!C81 -> do B2
A42: Prędkość frezowania | B42: =VLOOKUP(B41,A45:B46,2,FALSE) -> 5000
C44: MDF | D44: Wiórowa | H44: 1.1574074e-05 | I44: 0.00069444444 | J44: jaroma
...

Sheet TERMO
A1: Termoformierka | P1: Piła pozioma | Z1: Prasa Hydrauliczna
A2: Materiał | B2: =VLOOKUP(KALKULATOR!B1,Materiały_zakupowe!A:AC,19,FALSE) -> VIVAK | C2: =VLOOKUP(KALKULATOR!B1,Materiały_zakupowe!A:AC,25,FALSE) -> 0 | P2: materiał | Q2: =VLOOKUP(KALKULATOR!B1,Materiały_zakupowe!A:AD,20,FALSE) -> PET/VIVAK | W2: Piła pozioma Geiss | X2: stawka | Y2: =VLOOKUP(W2,Tabela13[[Maszyna]:[Stawka]],2,FALSE) -> 35 | Z2: ilość użytków | AA2: =KALKULATOR!D98 -> 1 | AF2: Prasa HYDRAULICZNA | AG2: stawka | AH2: =VLOOKUP(AF2,Tabela13[[Maszyna]:[Stawka]],2,FALSE) -> 55
A3: Grubość | B3: =VLOOKUP(KALKULATOR!B1,Materiały_zakupowe!A:AC,21,FALSE) -> 3 | P3: grubość | Q3: =VLOOKUP(KALKULATOR!B1,Materiały_zakupowe!A:AD,21,FALSE) -> 3 | Z3: nakład | AA3: =KALKULATOR!I1/KALKULATOR!D98 -> 100
A4: Kolor/maszyna | B4: metaliczne perłowe | C4: =IF(B4="metaliczne perłowe",1.2,1) -> 1.2 | P4: DŁ FORMATKI | Q4: =VLOOKUP(KALKULATOR!C98,A42:C46,3,FALSE) -> 1000 | AA4: =KALKULATOR!D101 -> TACKI
P5: ilość z formy | Q5: =KALKULATOR!D98 -> 1 | AA5: czas jednostkowy
A6: ilość z formy | B6: =KALKULATOR!D98 -> 1 | P6: RODZAJ ODKŁADANIA | Q6: =KALKULATOR!D104 -> UKŁADANIE I SORTOWANIE | S6: =VLOOKUP(Q6,P16:Q17,2,FALSE) -> 3 | Z6: POBRANIE WYTŁOCZKI | AA6: 0.00011574074 | AB6: =AA6*AA3 -> 0.011574074
A7: Nakład- ilosc przetłoczeń | B7: =KALKULATOR!I1/TERMO!B6 -> 100 | J7: operacja | K7: =VLOOKUP(L7,A34:O40,10,FALSE) -> 0.309375 | L7: =MIN(A34:A40) -> 572.25 | P7: WILKOŚĆ WYTŁOCZKI | Q7: =KALKULATOR!E104 -> do 0,5m | S7: =VLOOKUP(Q7,T15:U17,2,FALSE) -> 5.787037e-05 | Z7: NAŁOŻENIE PŁYTY | AA7: 4.6296296e-05 | AB7: =AA7*AD8*AA3 -> 0.0046296296
A8: Stempel | B8: =KALKULATOR!E98 -> NIE | J8: przezbrojenie | K8: =VLOOKUP(L7,A34:O40,11,FALSE) -> 0.03125 | L8: =VLOOKUP(L7,A34:P40,15,FALSE) -> 52.5 | P8: ilosc formatek | Q8: =KALKULATOR!I1/KALKULATOR!D98 -> 100 | U8: Operacja | V8: =((Q4/1000)/Q9/1440)*Q8+U19*Q8+S7*Q8*S6*Q5 -> 0.034060847 | W8: =V8*24*$Y$2 -> 28.611111 | Z8: UDEŻENIE PRASY | AA8: 3.4722222e-05 | AB8: =AA8*AD8*AA3 -> 0.0034722222 | AC8: ilość uderzeń | AD8: =ROUNDUP(AA2/3,0) -> 1 | AF8: Operacja | AG8: =VLOOKUP(AA4,AA14:AB15,2,FALSE) -> 0.076736111 | AH8: =AG8*24*$AH$2 -> 101.29167
A9: Gabaryt | B9: =IF(C2="rolka","z roli",KALKULATOR!C98) -> 750x1000 | P9: prędkość | Q9: =VLOOKUP(Q2,P21:X28,MATCH(Q3,P21:X21),FALSE)*Q20 -> 5.25 | U9: Przezbrojenie | V9: 0.0069444444 | W9: =V9*24*$Y$2 -> 5.8333333 | Z9: ZDJĘCIE SPADU | AA9: 9.2592593e-05 | AB9: =AA9*AA3 -> 0.0092592593 | AF9: Przezbrojenie | AG9: 0.020833333 | AH9: =AG9*24*$AH$2 -> 27.5
A10: St. trudności | B10: 1.15 | Z10: ZDJĘCIE PŁYTY | AA10: 4.6296296e-05 | AB10: =AA10*AA3 -> 0.0046296296
Z11: WYJĘCIE 1 WYTŁOCZKI | AA11: 5.787037e-05 | AB11: =AA11*AA2*AA3 -> 0.005787037
AA14: TACKI | AB14: =1.5*1.3*SUM(AB6:AB11) -> 0.076736111
T15: do 0,5m | U15: 5.787037e-05 | AA15: POZOSTAŁE | AB15: =1.5*SUM(AB6:AB11) -> 0.059027778
P16: UKŁADANIE I SORTOWANIE | Q16: 3 | T16: od 0,5m do 1m | U16: 0.00011574074 | AA16: Przezbrojenie | AB16: 0.020833333
P17: OWIJANIE INDYWIDUALNE | Q17: 5 | T17: powyżej 1m | U17: 0.00017361111
T19: pobranie wytłoczki | U19: 3.4722222e-05
Q20: 3.5
A21: GRUBOŚĆ MATERIAŁU (MM) | B21: PLEXI | C21: PCV | D21: TUPET /PET / AXPET | E21: HIPS / ABS | F21: VIVAK | H21: =MIN(H34:H40) -> 1 | Q21: 0.5 | S21: 1 | T21: 1.5 | U21: 2 | V21: 3 | W21: 4 | X21: 5
A22: 0.3 | B22: X | C22: X | D22: X | E22: X | F22: 0.00040509259 | P22: ABS | Q22: X | S22: X | T22: X | U22: 1 | V22: 1 | W22: 1.5 | X22: 2
A23: 0.5 | B23: X | C23: 0.0011574074 | D23: 0.00075231481 | E23: 0.00069444444 | F23: 0.00069444444 | P23: HIPS | Q23: 0.33 | S23: 1 | T23: 1 | U23: 1 | V23: 1 | W23: 1.5 | X23: 1.5
A24: 0.8 | B24: X | C24: 0.0015046296 | D24: 0.0008912037 | E24: 0.00083333333 | F24: 0.00081018519 | P24: AXPET | Q24: 0.33 | S24: 0.5 | T24: 1.5 | U24: X | V24: X | W24: X | X24: X
A25: 1 | B25: X | C25: 0.0018518519 | D25: 0.001099537 | E25: 0.0010416667 | F25: 0.0010416667 | P25: PET/VIVAK | Q25: 0.33 | S25: 0.5 | T25: 1.5 | U25: 1.5 | V25: 1.5 | W25: X | X25: X
A26: 1.5 | B26: 0.0019097222 | C26: 0.0024305556 | D26: 0.0015625 | E26: 0.0012731481 | F26: 0.0015625 | P26: PCV | Q26: 0.33 | S26: 0.33 | T26: 1.5 | U26: 1.5 | V26: 1.5 | W26: X | X26: X
A27: 2 | B27: 0.0020833333 | C27: 0.0027777778 | D27: 0.0022569444 | E27: 0.0017361111 | F27: 0.0019097222 | P27: PMMA | Q27: X | S27: X | T27: X | U27: 0.33 | V27: 0.33 | W27: 1.5 | X27: 1.5
A28: 3 | B28: 0.0039930556 | C28: 0.0031828704 | D28: X | E28: 0.0022569444 | F28: 0.0021412037 | P28: PMMA HI | Q28: X | S28: X | T28: X | U28: 0.66 | V28: 1 | W28: 1.5 | X28: 1.5
A29: 4 | B29: 0.0047222222 | C29: 0.0036458333 | D29: X | E29: 0.0030671296 | F29: 0.0026041667
A30: 5 | B30: 0.0053819444 | C30: 0.0046875 | D30: X | E30: 0.0039930556 | F30: 0.0032986111
J31: czas 1 sztuki | K31: =VLOOKUP(B3,A21:F30,MATCH(B2,A21:F21,0),FALSE)*B10*C4 -> 0.0029548611
A33: koszt operacji | C33: MAX wymiar | D33: wymiana materiału | E33: Wydajność | F33: Stempel | J33: Operacja | K33: Przezbrojenie | L33: Suma | M33: stawka maszyny
A34: =IFERROR(IF(VLOOKUP(I34,$R$34:$R$40,1,FALSE)=I34,L34*24*M34,"ograniczenie maszyny"),"ograniczenie maszyny") -> ograniczenie maszyny | B34: Z ROLI SB 53, TF 105 | C34: z roli | D34: 5.787037e-05 | E34: 1 | F34: TAK | H34: =IF($B$9="z roli",IF($B$9=C34,1,""),IF(G34>=$G$44,IF($B$8="NIE",1+MAX($H$33:H33),IF(F34="NIE","",1+MAX($H$33:H33))),"")) | I34: =B34 -> Z ROLI SB 53, TF 105 | J34: =($K$31*E34+D34)*$B$7 -> 0.30127315 | K34: 0.020833333 | L34: =J34+K34 -> 0.32210648 | M34: 80 | N34: =J34*$M34*24 -> 578.44444 | O34: =K34*$M34*24 -> 40 | Q34: 1 | R34: =IFERROR(VLOOKUP(Q34,$H$34:$I$40,2,FALSE),"") -> Z PŁYTY TF 103, TF 104
A35: =IFERROR(IF(VLOOKUP(I35,$R$34:$R$40,1,FALSE)=I35,L35*24*M35,"ograniczenie maszyny"),"ograniczenie maszyny") -> 572.25 | B35: Z PŁYTY TF 103, TF 104 | C35: 750x1000 | D35: 0.00013888889 | E35: 1 | F35: NIE | G35: =LEFT(C35,SEARCH("x",C35)-1)*RIGHT(C35,LEN(C35)-SEARCH("x",C35))/(1000^2) -> 0.75 | H35: =IF($B$9="z roli",IF($B$9=C35,1,""),IF(G35>=$G$44,IF($B$8="NIE",1+MAX($H$33:H34),IF(F35="NIE","",1+MAX($H$33:H34))),"")) -> 1 | I35: =B35 -> Z PŁYTY TF 103, TF 104 | J35: =($K$31*E35+D35)*$B$7 -> 0.309375 | K35: 0.03125 | L35: =J35+K35 -> 0.340625 | M35: 70 | N35: =J35*$M35*24 -> 519.75 | O35: =K35*$M35*24 -> 52.5 | Q35: 2 | R35: =IFERROR(VLOOKUP(Q35,$H$34:$I$40,2,FALSE),"") -> Z PŁYTY TF 102
A36: =IFERROR(IF(VLOOKUP(I36,$R$34:$R$40,1,FALSE)=I36,L36*24*M36,"ograniczenie maszyny"),"ograniczenie maszyny") -> 671.53333 | B36: Z PŁYTY TF 102 | C36: 750x1000 | D36: 0.00013888889 | E36: 1.2 | F36: TAK | G36: =LEFT(C36,SEARCH("x",C36)-1)*RIGHT(C36,LEN(C36)-SEARCH("x",C36))/(1000^2) -> 0.75 | H36: =IF($B$9="z roli",IF($B$9=C36,1,""),IF(G36>=$G$44,IF($B$8="NIE",1+MAX($H$33:H35),IF(F36="NIE","",1+MAX($H$33:H35))),"")) -> 2 | I36: =B36 -> Z PŁYTY TF 102 | J36: =($K$31*E36+D36)*$B$7 -> 0.36847222 | K36: 0.03125 | L36: =J36+K36 -> 0.39972222 | M36: 70 | N36: =J36*$M36*24 -> 619.03333 | O36: =K36*$M36*24 -> 52.5 | Q36: 3 | R36: =IFERROR(VLOOKUP(Q36,$H$34:$I$40,2,FALSE),"") -> Z PŁYTY TF 1
A37: =IFERROR(IF(VLOOKUP(I37,$R$34:$R$40,1,FALSE)=I37,L37*24*M37,"ograniczenie maszyny"),"ograniczenie maszyny") -> 671.53333 | B37: Z PŁYTY TF 1 | C37: 1000x1000 | D37: 0.00013888889 | E37: 1.2 | F37: TAK | G37: =LEFT(C37,SEARCH("x",C37)-1)*RIGHT(C37,LEN(C37)-SEARCH("x",C37))/(1000^2) -> 1 | H37: =IF($B$9="z roli",IF($B$9=C37,1,""),IF(G37>=$G$44,IF($B$8="NIE",1+MAX($H$33:H36),IF(F37="NIE","",1+MAX($H$33:H36))),"")) -> 3 | I37: =B37 -> Z PŁYTY TF 1 | J37: =($K$31*E37+D37)*$B$7 -> 0.36847222 | K37: 0.03125 | L37: =J37+K37 -> 0.39972222 | M37: 70 | N37: =J37*$M37*24 -> 619.03333 | O37: =K37*$M37*24 -> 52.5 | Q37: 4 | R37: =IFERROR(VLOOKUP(Q37,$H$34:$I$40,2,FALSE),"") -> Z PŁYTY TF 12G 2 PIECE
A38: =IFERROR(IF(VLOOKUP(I38,$R$34:$R$40,1,FALSE)=I38,L38*24*M38,"ograniczenie maszyny"),"ograniczenie maszyny") -> 589.75 | B38: Z PŁYTY TF 12G 2 PIECE | C38: 1000x1000 | D38: 0.00013888889 | E38: 1 | F38: TAK | G38: =LEFT(C38,SEARCH("x",C38)-1)*RIGHT(C38,LEN(C38)-SEARCH("x",C38))/(1000^2) -> 1 | H38: =IF($B$9="z roli",IF($B$9=C38,1,""),IF(G38>=$G$44,IF($B$8="NIE",1+MAX($H$33:H37),IF(F38="NIE","",1+MAX($H$33:H37))),"")) -> 4 | I38: =B38 -> Z PŁYTY TF 12G 2 PIECE | J38: =($K$31*E38+D38)*$B$7 -> 0.309375 | K38: 0.041666667 | L38: =J38+K38 -> 0.35104167 | M38: 70 | N38: =J38*$M38*24 -> 519.75 | O38: =K38*$M38*24 -> 70 | Q38: 5 | R38: =IFERROR(VLOOKUP(Q38,$H$34:$I$40,2,FALSE),"") -> Z PŁYTY TF 15 | U38: =R38 -> Z PŁYTY TF 15
A39: =IFERROR(IF(VLOOKUP(I39,$R$34:$R$40,1,FALSE)=I39,L39*24*M39,"ograniczenie maszyny"),"ograniczenie maszyny") -> 731.49111 | B39: Z PŁYTY TF 15 | C39: 1000x1500 | D39: 0.00023148148 | E39: 1.07 | F39: TAK | G39: =LEFT(C39,SEARCH("x",C39)-1)*RIGHT(C39,LEN(C39)-SEARCH("x",C39))/(1000^2) -> 1.5 | H39: =IF($B$9="z roli",IF($B$9=C39,1,""),IF(G39>=$G$44,IF($B$8="NIE",1+MAX($H$33:H38),IF(F39="NIE","",1+MAX($H$33:H38))),"")) -> 5 | I39: =B39 -> Z PŁYTY TF 15 | J39: =($K$31*E39+D39)*$B$7 -> 0.33931829 | K39: 0.041666667 | L39: =J39+K39 -> 0.38098495 | M39: 80 | N39: =J39*$M39*24 -> 651.49111 | O39: =K39*$M39*24 -> 80 | Q39: 6 | R39: =IFERROR(VLOOKUP(Q39,$H$34:$I$40,2,FALSE),"") -> Z PŁYTY TF 25G 2 PIECE | U39: =R39 -> Z PŁYTY TF 25G 2 PIECE
A40: =IFERROR(IF(VLOOKUP(I40,$R$34:$R$40,1,FALSE)=I40,L40*24*M40,"ograniczenie maszyny"),"ograniczenie maszyny") -> 1786.5 | B40: Z PŁYTY TF 25G 2 PIECE | C40: 1500x2500 | D40: 0.00034722222 | E40: 1 | F40: TAK | G40: =LEFT(C40,SEARCH("x",C40)-1)*RIGHT(C40,LEN(C40)-SEARCH("x",C40))/(1000^2) -> 3.75 | H40: =IF($B$9="z roli",IF($B$9=C40,1,""),IF(G40>=$G$44,IF($B$8="NIE",1+MAX($H$33:H39),IF(F40="NIE","",1+MAX($H$33:H39))),"")) -> 6 | I40: =B40 -> Z PŁYTY TF 25G 2 PIECE | J40: =($K$31*E40+D40)*$B$7 -> 0.33020833 | K40: 0.083333333 | L40: =J40+K40 -> 0.41354167 | M40: 180 | N40: =J40*$M40*24 -> 1426.5 | O40: =K40*$M40*24 -> 360 | Q40: 7 | R40: =IFERROR(VLOOKUP(Q40,$H$34:$I$40,2,FALSE),"") | U40: =R40
A42: Z roli | B42: 700 | C42: 700
A43: 750x1000 | B43: 750x1000 | C43: 1000
A44: 1000x1000 | B44: 1000x1000 | C44: 1000 | G44: =LEFT(B9,SEARCH("x",B9)-1)*RIGHT(B9,LEN(B9)-SEARCH("x",B9))/(1000^2) -> 0.75
A45: 1000x1500 | B45: 1000x1500 | C45: 1500
...

Sheet FREZ
A1: FREZOWANIE | J1: CIĘCIE
A2: Materiał | B2: =VLOOKUP(KALKULATOR!B1,Materiały_zakupowe!A:AD,5,FALSE) -> VIVAK/PET/TUPET/AXPET | F2: Frezarka FESTOOL I | G2: Stawka maszyny | H2: =VLOOKUP(F2,Tabela13[[Maszyna]:[Stawka]],2,FALSE) -> 35 | J2: RODZAJ ELEMENTU | K2: =KALKULATOR!C112 -> WYTŁOCZKA | O2: Piła tarczowa DE WALT I | P2: stawkqa | Q2: =VLOOKUP(O2,Tabela13[[Maszyna]:[Stawka]],2,FALSE) -> 35
A3: ilość formatek | B3: =KALKULATOR!I1/KALKULATOR!D108 -> 100 | J3: DŁUGOŚĆ CIĘCUIA | K3: =KALKULATOR!E112 -> 200 | L3: 0.00069444444
A4: dł frezowania | B4: =KALKULATOR!E108 -> 250 | J4: ILOŚĆ FORMATEK | K4: =KALKULATOR!I1/KALKULATOR!D112 -> 100
A5: Rodzaj elementu | B5: =KALKULATOR!C108 -> WYTŁOCZKA OBRÓBKA NIEPROSTOLINIOWA | C5: 0.00069444444 | E5: WYTŁOCZKA OBRÓBKA NIEPROSTOLINIOWA
J7: PRĘDKOŚĆ | K7: =VLOOKUP(K2,J15:K17,2,FALSE) -> 1000
A8: Prędkość | B8: =VLOOKUP(B2,A15:E20,MATCH(B5,A15:E15,0),FALSE) -> 550 | E8: Operacja | F8: =B12*B3 -> 0.066287879 | G8: =F8*24*$H$2 -> 55.681818 | J8: min ciecie | K8: 0.00011574074 | N8: Operacja | O8: =K12*K4 -> 0.03125 | P8: =O8*24*$Q$2 -> 26.25
E9: Przezbrojenei | F9: 0.010416667 | G9: =F9*24*$H$2 -> 8.75 | N9: Przezbrojenei | O9: 0.010416667 | P9: =O9*24*$Q$2 -> 8.75
A10: frezowanie | B10: =B4/B8*C5 -> 0.00031565657 | J10: ciecie | K10: =IF(K3/K7*L3<K8,K8,K3/K7*L3) -> 0.00013888889
A11: założenie/odłożenie | B11: =HLOOKUP(B5,B15:E21,7,FALSE) -> 0.00034722222 | J11: założenie | K11: =VLOOKUP(K2,J15:L17,3,FALSE) -> 0.00017361111
A12: Suma | B12: =SUM(B10:B11) -> 0.00066287879 | J12: suma | K12: =SUM(K10:K11) -> 0.0003125
A15: MATERIAŁ | B15: PŁASKA OBRÓBKA PROSTOLINIOWA | C15: WYTŁOCZKA OBRÓBKA PROSTOLINIOWA | D15: PŁASKA OBRÓBKA NIEPROSTOLINIOWA | E15: WYTŁOCZKA OBRÓBKA NIEPROSTOLINIOWA | J15: WYTŁOCZKA | K15: 1000 | L15: 0.00017361111
A16: PLEXI | B16: 950 | C16: 850 | D16: 470 | E16: 400 | J16: PŁASKIE | K16: 1000 | L16: 6.9444444e-05
A17: PCV | B17: 900 | C17: 900 | D17: 450 | E17: 450 | J17: CIĘCIE WSTĘPNE | K17: 2000 | L17: 6.9444444e-05
A18: PCV SPIENIONE | B18: 1100 | C18: 1000 | D18: 550 | E18: 500
A19: VIVAK/PET/TUPET/AXPET | B19: 1200 | C19: 1100 | D19: 600 | E19: 550
A20: HIPS | B20: 1100 | C20: 1000 | D20: 550 | E20: 500
B21: 0.00023148148 | C21: 0.00034722222 | D21: 0.00023148148 | E21: 0.00034722222
A29: frezowanie std | J29: ciecie std
A30: Nakład | B30: =KALKULATOR!I1/KALKULATOR!E116 -> 100 | H30: stawka maszyny | I30: 60 | J30: Nakład | K30: =KALKULATOR!I1/KALKULATOR!E120 -> 100 | Q30: stawka maszyny | R30: 60
A31: ELEMENT | B31: =KALKULATOR!C116 -> TACKI FREZOWANIE FASOLKI 1PKT | J31: ELEMENT | K31: =KALKULATOR!C120 -> KĄTOWNIK WTRYSKOWY
A32: WYRÓB/ OPERACJA | B32: =KALKULATOR!D116 -> TACKI FREZOWANIE FASOLKI 1PKT | G32: Operacja | H32: =VLOOKUP(B31&B32,A91:E106,5,FALSE) -> 0.020833333 | I32: =H32*24*$I$30 -> 30 | J32: WYRÓB/ OPERACJA | K32: =KALKULATOR!D120 -> CIĘCIE NÓŻEK | P32: Operacja | Q32: =VLOOKUP(K31&K32,J91:N137,5,FALSE) -> 0.027777778 | R32: =Q32*24*R30 -> 40
G33: Przezbrojenei | H33: 0.0034722222 | I33: =H33*24*$I$30 -> 5 | P33: Przezbrojenei | Q33: 0.0034722222 | R33: =Q33*24*R30 -> 5
A35: ELEMENT | B35: WYRÓB OPERACJA | J35: ELEMENT | K35: WYRÓB OPERACJA
A36: ŁĄCZNIK ELIPSA MAŁA | B36: FREZOWANIE ŁUKU | C36: =IF($B$31=A36,MAX(C$35:$C35)+1,"") | D36: =B36 -> FREZOWANIE ŁUKU | E36: 1 | F36: =IFERROR(VLOOKUP(E36,$C$36:$D$52,2,FALSE),"") -> TACKI FREZOWANIE FASOLKI 1PKT | G36: =IF(F36="","",E36) -> 1 | J36: ŁĄCZNIK ELIPSA MAŁA | K36: CIĘCIE | L36: =IF($K$31=J36,MAX(L$35:$L35)+1,"") | M36: =K36 -> CIĘCIE | N36: 1 | O36: =IFERROR(VLOOKUP(N36,$L$36:$M$52,2,FALSE),"") -> CIĘCIE ŁĄCZNIKA | P36: =IF(O36="","",N36) -> 1
A37: ŁĄCZNIK ELIPSA MAŁA | B37: FREZOWANIE KANAŁU | C37: =IF($B$31=A37,MAX(C$35:$C36)+1,"") | D37: =B37 -> FREZOWANIE KANAŁU | E37: 2 | F37: =IFERROR(VLOOKUP(E37,$C$36:$D$52,2,FALSE),"") | G37: =IF(F37="","",E37) | J37: ŁĄCZNIK ELIPSA DUŻA | K37: CIĘCIE | L37: =IF($K$31=J37,MAX(L$35:$L36)+1,"") | M37: =K37 -> CIĘCIE | N37: 2 | O37: =IFERROR(VLOOKUP(N37,$L$36:$M$52,2,FALSE),"") -> CIĘCIE NÓŻEK | P37: =IF(O37="","",N37) -> 2
A38: ŁĄCZNIK ELIPSA DUŻA | B38: FREZOWANIE ŁUKU | C38: =IF($B$31=A38,MAX(C$35:$C37)+1,"") | D38: =B38 -> FREZOWANIE ŁUKU | E38: 3 | F38: =IFERROR(VLOOKUP(E38,$C$36:$D$52,2,FALSE),"") | G38: =IF(F38="","",E38) | J38: ŁĄCZNIK PT | K38: CIĘCIE | L38: =IF($K$31=J38,MAX(L$35:$L37)+1,"") | M38: =K38 -> CIĘCIE | N38: 3 | O38: =IFERROR(VLOOKUP(N38,$L$36:$M$52,2,FALSE),"") -> CIĘCIE ŁĄCZNIKA TOPEROWEGO | P38: =IF(O38="","",N38) -> 3
A39: ŁĄCZNIK ELIPSA DUŻA | B39: FREZOWANIE KANAŁU | C39: =IF($B$31=A39,MAX(C$35:$C38)+1,"") | D39: =B39 -> FREZOWANIE KANAŁU | E39: 4 | F39: =IFERROR(VLOOKUP(E39,$C$36:$D$52,2,FALSE),"") | G39: =IF(F39="","",E39) | J39: KĄTOWNIK WTRYSKOWY | K39: CIĘCIE ŁĄCZNIKA | L39: =IF($K$31=J39,MAX(L$35:$L38)+1,"") -> 1 | M39: =K39 -> CIĘCIE ŁĄCZNIKA | N39: 4 | O39: =IFERROR(VLOOKUP(N39,$L$36:$M$52,2,FALSE),"") | P39: =IF(O39="","",N39)
A40: ŁĄCZNIK PT | B40: FREZOWANIE ŁUKU | C40: =IF($B$31=A40,MAX(C$35:$C39)+1,"") | D40: =B40 -> FREZOWANIE ŁUKU | E40: 5 | F40: =IFERROR(VLOOKUP(E40,$C$36:$D$52,2,FALSE),"") | G40: =IF(F40="","",E40) | J40: KĄTOWNIK WTRYSKOWY | K40: CIĘCIE NÓŻEK | L40: =IF($K$31=J40,MAX(L$35:$L39)+1,"") -> 2 | M40: =K40 -> CIĘCIE NÓŻEK | N40: 5 | O40: =IFERROR(VLOOKUP(N40,$L$36:$M$52,2,FALSE),"") | P40: =IF(O40="","",N40)
A41: ŁĄCZNIK PT | B41: FREZOWANIE KANAŁU | C41: =IF($B$31=A41,MAX(C$35:$C40)+1,"") | D41: =B41 -> FREZOWANIE KANAŁU | E41: 6 | F41: =IFERROR(VLOOKUP(E41,$C$36:$D$52,2,FALSE),"") | G41: =IF(F41="","",E41) | J41: KĄTOWNIK WTRYSKOWY | K41: CIĘCIE ŁĄCZNIKA TOPEROWEGO | L41: =IF($K$31=J41,MAX(L$35:$L40)+1,"") -> 3 | M41: =K41 -> CIĘCIE ŁĄCZNIKA TOPEROWEGO | N41: 6 | O41: =IFERROR(VLOOKUP(N41,$L$36:$M$52,2,FALSE),"") | P41: =IF(O41="","",N41)
A42: ŁĄCZNIK WING | B42: FREZOWANIE ŁUKU | C42: =IF($B$31=A42,MAX(C$35:$C41)+1,"") | D42: =B42 -> FREZOWANIE ŁUKU | E42: 7 | F42: =IFERROR(VLOOKUP(E42,$C$36:$D$52,2,FALSE),"") | G42: =IF(F42="","",E42) | J42: ŁĄCZNIK WING | K42: CIĘCIE | L42: =IF($K$31=J42,MAX(L$35:$L41)+1,"") | M42: =K42 -> CIĘCIE | N42: 7 | O42: =IFERROR(VLOOKUP(N42,$L$36:$M$52,2,FALSE),"") | P42: =IF(O42="","",N42)
A43: ŁĄCZNIK WING | B43: FREZOWANIE KANAŁU | C43: =IF($B$31=A43,MAX(C$35:$C42)+1,"") | D43: =B43 -> FREZOWANIE KANAŁU | E43: 8 | F43: =IFERROR(VLOOKUP(E43,$C$36:$D$52,2,FALSE),"") | G43: =IF(F43="","",E43) | J43: ŁĄCZNIK TRIANGLE | K43: CIĘCIE ŁĄCZNIKA | L43: =IF($K$31=J43,MAX(L$35:$L42)+1,"") | M43: =K43 -> CIĘCIE ŁĄCZNIKA | N43: 8 | O43: =IFERROR(VLOOKUP(N43,$L$36:$M$52,2,FALSE),"") | P43: =IF(O43="","",N43)
A44: ŁĄCZNIK KR | B44: FREZOWANIE ŁUKU | C44: =IF($B$31=A44,MAX(C$35:$C43)+1,"") | D44: =B44 -> FREZOWANIE ŁUKU | E44: 9 | F44: =IFERROR(VLOOKUP(E44,$C$36:$D$52,2,FALSE),"") | G44: =IF(F44="","",E44) | J44: ŁĄCZNIK TRIANGLE | K44: CIĘCIE ŁĄCZNIKA TOPEROWEGO | L44: =IF($K$31=J44,MAX(L$35:$L43)+1,"") | M44: =K44 -> CIĘCIE ŁĄCZNIKA TOPEROWEGO | N44: 9 | O44: =IFERROR(VLOOKUP(N44,$L$36:$M$52,2,FALSE),"") | P44: =IF(O44="","",N44)
A45: ŁĄCZNIK KR | B45: FREZOWANIE KANAŁU | C45: =IF($B$31=A45,MAX(C$35:$C44)+1,"") | D45: =B45 -> FREZOWANIE KANAŁU | E45: 10 | F45: =IFERROR(VLOOKUP(E45,$C$36:$D$52,2,FALSE),"") | G45: =IF(F45="","",E45) | J45: ŁĄCZNIK KR | K45: CIĘCIE | L45: =IF($K$31=J45,MAX(L$35:$L44)+1,"") | M45: =K45 -> CIĘCIE | N45: 10 | O45: =IFERROR(VLOOKUP(N45,$L$36:$M$52,2,FALSE),"") | P45: =IF(O45="","",N45)
A46: MISA SŁUP | B46: FREZOWANIE | C46: =IF($B$31=A46,MAX(C$35:$C45)+1,"") | D46: =B46 -> FREZOWANIE | E46: 11 | F46: =IFERROR(VLOOKUP(E46,$C$36:$D$52,2,FALSE),"") | G46: =IF(F46="","",E46) | J46: RURA FI 32 | K46: CIĘCIE ŁĄCZNIKA | L46: =IF($K$31=J46,MAX(L$35:$L45)+1,"") | M46: =K46 -> CIĘCIE ŁĄCZNIKA | N46: 11 | O46: =IFERROR(VLOOKUP(N46,$L$36:$M$52,2,FALSE),"") | P46: =IF(O46="","",N46)
A47: KĄTOWNIK WTRYSKOWY | B47: FREZOWANIE NÓŻEK DO PODESTÓW | C47: =IF($B$31=A47,MAX(C$35:$C46)+1,"") | D47: =B47 -> FREZOWANIE NÓŻEK DO PODESTÓW | E47: 12 | F47: =IFERROR(VLOOKUP(E47,$C$36:$D$52,2,FALSE),"") | G47: =IF(F47="","",E47) | J47: RURA FI 32 | K47: NACINANIE ŁĄCZNIKA | L47: =IF($K$31=J47,MAX(L$35:$L46)+1,"") | M47: =K47 -> NACINANIE ŁĄCZNIKA | N47: 12 | O47: =IFERROR(VLOOKUP(N47,$L$36:$M$52,2,FALSE),"") | P47: =IF(O47="","",N47)
... A51: ŁĄCZNIK PÓŁKA OKRĄGŁA | B51: FREZOWANIE ŁĄCZNIKA (2 STR.) | C51: =IF($B$31=A51,MAX(C$35:$C50)+1,"") | D51: =B51 -> FREZOWANIE ŁĄCZNIKA (2 STR.) | E51: 16 | F51: =IFERROR(VLOOKUP(E51,$C$36:$D$52,2,FALSE),"") | G51: =IF(F51="","",E51) | J51: RURA FI 32 | K51: FREZ. ŁĄCZNIKA TOPEROWEGO POD GRAFIKĘ | L51: =IF($K$31=J51,MAX(L$35:$L50)+1,"") | M51: =K51 -> FREZ. ŁĄCZNIKA TOPEROWEGO POD GRAFIKĘ | N51: 16 | O51: =IFERROR(VLOOKUP(N51,$L$36:$M$52,2,FALSE),"") | P51: =IF(O51="","",N51)
E52: 17 | F52: =IFERROR(VLOOKUP(E52,$C$36:$D$52,2,FALSE),"") | G52: =IF(F52="","",E52) | J52: RURA FI 42 | K52: CIĘCIE ŁĄCZNIKA | L52: =IF($K$31=J52,MAX(L$35:$L51)+1,"") | M52: =K52 -> CIĘCIE ŁĄCZNIKA | N52: 17 | O52: =IFERROR(VLOOKUP(N52,$L$36:$M$52,2,FALSE),"") | P52: =IF(O52="","",N52)
J53: RURA FI 42 | K53: NACINANIE ŁĄCZNIKA | L53: =IF($K$31=J53,MAX(L$35:$L52)+1,"") | M53: =K53 -> NACINANIE ŁĄCZNIKA
J54: RURA FI 42 | K54: CIĘCIE NÓŻEK | L54: =IF($K$31=J54,MAX(L$35:$L53)+1,"") | M54: =K54 -> CIĘCIE NÓŻEK
...

Sheet FORMY
A1: Ploter frezujący | I1: FREZOWANIE INFOTEC | Q1: LASER
A2: Materiał | B2: =VLOOKUP(KALKULATOR!B1,Materiały_zakupowe!A:AA,16,FALSE) -> VIVAK / PET | E2: Ploter A4004 | F2: Stawka maszyny | G2: =VLOOKUP(E2,Stawki_maszyn!B:C,2,FALSE) -> 50 | I2: materiał | J2: =VLOOKUP(KALKULATOR!B1,Materiały_zakupowe!A:AD,13,FALSE) -> PET | N2: INFOTEC 3121 | O2: stawka | P2: =VLOOKUP(N2,Stawki_maszyn!B:D,2,FALSE) -> 50 | Q2: MATERIAŁ | R2: =VLOOKUP(KALKULATOR!B1,Materiały_zakupowe!A:AD,15,FALSE) -> VIVAK / PET itp. | V2: Ploter laserowy NRG 608 | W2: stawka maszyny | X2: =VLOOKUP(V2,Stawki_maszyn!B:C,2,FALSE) -> 50
A3: ILOŚĆ UŻYTKÓW | B3: =KALKULATOR!C85 -> 1 | I3: ilość użytków | J3: =KALKULATOR!C89 -> 1 | Q3: GRUBOŚĆ | R3: =VLOOKUP(KALKULATOR!B1,Materiały_zakupowe!A:AD,21,FALSE) -> 3
A4: ilość formatek | B4: =KALKULATOR!I1/KALKULATOR!C85 -> 100 | I4: ilość formatek | J4: =KALKULATOR!I1/KALKULATOR!C89 -> 100 | Q4: ILOŚĆ UŻYTKÓW | R4: =KALKULATOR!C94 -> 1
A5: DŁUGOŚĆ FREZOWANIA [MM] | B5: =KALKULATOR!D85 -> 2000 | I5: długość frezowania [mm] | J5: =KALKULATOR!D89 -> 2500 | K5: 0.00069444444 | Q5: ILOŚĆ FORMATEK | R5: =KALKULATOR!I1/KALKULATOR!C94 -> 100
A6: RODZAJ FORM | B6: =KALKULATOR!E85 -> 2D | C6: 0.00069444444 | Q6: DŁUGOŚĆ FREZOWANIA | R6: =KALKULATOR!D94 -> 2000 | S6: 0.00069444444
A7: Prędkość | B7: =VLOOKUP(B2,A20:B27,2,FALSE) -> 1000 | I7: prędkość | J7: =HLOOKUP(J2,I19:O20,2,FALSE) -> 2700 | V7: O ile stary wolniejszy od nowego | Y7: 1
Q8: Prędkość | R8: =VLOOKUP(R2,Q20:AB24,MATCH(R3,Q20:AB20,0),FALSE) -> 3420
A9: założenie | B9: =C9*B3 -> 0.00034722222 | C9: 0.00034722222 | E9: Operacja | F9: =B13*B4 -> 0.27777778 | G9: =F9*24*$G$2 -> 333.33333 | I9: Czas frezowania | J9: =J5/J7*K5 -> 0.00064300412 | V9: 0.0034722222 | X9: nowy laser | Z9: stary laser
A10: frez | B10: =B5/B7*C6 -> 0.0013888889 | E10: Przezbrojenei | F10: =VLOOKUP(B6,A17:B18,2,FALSE) -> 0.013888889 | G10: =F10*24*$G$2 -> 16.666667 | I10: Czas wymiany formatki | J10: =VLOOKUP(J3,I23:J28,2,TRUE)*J3 -> 0.00052083333 | Q10: czas zdjęcia elementów | R10: =S10*R4 -> 3.4722222e-05 | S10: 3.4722222e-05 | U10: operacja | V10: =R15*R5 -> 0.08806449 | W10: Operacja łaczny czas | X10: =(V10/(1/24))*V9+V10 -> 0.095403197 | Y10: =V10*24*$X$2 -> 105.67739 | Z10: =X10*Y7 -> 0.095403197
B11: 0.00069444444 | I11: Czas wymiany narzędzi | J11: 0.0013888889 | Q11: zmiana ścieżki | R11: =S11*R4 -> 9.2592593e-05 | S11: 9.2592593e-05 | W11: Przezbrojenei | X11: 0.013888889 | Y11: =X11*24*$X$2 -> 16.666667 | Z11: 0.013888889
A12: zmiana sciezki | B12: =C12*B3 -> 0.00034722222 | C12: 0.00034722222 | I12: Czas zmiany ścieżek | J12: =K12*J3 -> 0.00013888889 | K12: 0.00013888889 | Q12: wymiana formatki | R12: 0.00034722222
B13: =SUM(B9:B12)*VLOOKUP(B6,A17:C31,3,FALSE) -> 0.0027777778 | I13: czas dod | J13: =IF(J2="plexa",N23,N24) -> 0.00011574074 | N13: Operacja | O13: =J14*J4 -> 0.2807356 | P13: =O13*24*$P$2 -> 336.88272 | Q13: czas cięcia | R13: =R6/R8*S6 -> 0.00040610786
J14: =SUM(J9:J13) -> 0.002807356 | N14: Przezbrojenei | O14: 0.013888889 | P14: =O14*24*$P$2 -> 16.666667
R15: =SUM(R10:R13) -> 0.0008806449
A16: Przezbrojenie
A17: 2D | B17: 0.013888889 | C17: 1
A18: 3D | B18: 0.020833333 | C18: 2
A19: Prędkości | J19: PLEXA | K19: HIPS | L19: PCV | M19: PCV SP. | N19: PET | O19: DIBOND
A20: PLEXI | B20: 1000 | I20: Posuw [mm/min | J20: 3000 | K20: 2700 | L20: 3000 | M20: 4200 | N20: 2700 | O20: 4200 | Q20: MATERIAŁ | R20: 0.5 | S20: 0.8 | T20: 1 | U20: 1.5 | V20: 2 | W20: 3 | X20: 4 | Y20: 5 | Z20: 6 | AA20: 8 | AB20: 10
A21: PCV | B21: 1200 | Q21: PLEXI | R21: x | S21: x | T21: x | U21: 5400 | V21: 4800 | W21: 3600 | X21: 2700 | Y21: 2100 | Z21: 1500 | AA21: 900 | AB21: 600
A22: PCV SPIENIONE | B22: 1500 | Q22: SKLEJKA | R22: x | S22: x | T22: x | U22: x | V22: 2100 | W22: 2100 | X22: 1800 | Y22: 1500 | Z22: 1200 | AA22: 900 | AB22: 600
A23: DIBOND | B23: 500 | I23: 0 | J23: 0.00052083333 | N23: 0.00017361111 | Q23: VIVAK / PET itp. | R23: 8400 | S23: 7500 | T23: 6000 | U23: 5100 | V23: 4200 | W23: 3420 | X23: x | Y23: x | Z23: x | AA23: x | AB23: x
A24: ALUMINIUM | B24: 500 | I24: 2 | J24: 0.00034722222 | N24: 0.00011574074 | Q24: HIPS | R24: x | S24: x | T24: 5400 | U24: 4500 | V24: 3600 | W24: 2100 | X24: 1500 | Y24: x | Z24: x | AA24: x | AB24: x
A25: PŁYTA OSB, MDF, WIÓROWA | B25: 1600 | I25: 5 | J25: 0.00023148148
A26: VIVAK / PET | B26: 1000 | I26: 10 | J26: 0.00017361111
A27: HIPS | B27: 1600 | I27: 11 | J27: 0.00011574074
I28: 21 | J28: 5.787037e-05

Sheet Materiały_zakupowe
B1: =COLUMN(B1) -> 2 | C1: =COLUMN(C1) -> 3 | D1: =COLUMN(D1) -> 4 | E1: =COLUMN(E1) -> 5 | F1: =COLUMN(F1) -> 6 | G1: =COLUMN(G1) -> 7 | H1: =COLUMN(H1) -> 8 | I1: =COLUMN(I1) -> 9 | ... AI1: =COLUMN(AI1) -> 35
I2: offset | J2: sito | K2: kaszerowany | L2: Pozostałe
A3: Indeks | B3: Nazwa | C3: Nazwa rozwinięta | D3: Jednostka miary | E3: FREZARKI | F3: PLOTER DRUKUJĄCY ROLAND | G3: PLOTER TNĄCY | H3: FORMATYZERKA | I3: GILOTYNA | J3: GILOTYNA2 | K3: GILOTYNA3 | L3: GILOTYNA4 | M3: INFOTEC | N3: KASZEROWANIE | O3: LASER | P3: PLOTERY FREZUJĄCE | Q3: DRUK SITO | R3: SZTANCOWANIE wyr tworz | S3: TERMOFORMOWANIE | T3: PIŁA POZIOMA | U3: GRUBOŚĆ | V3: Metaliczne perłowe do termoformowania | W3: Centrum HOMAG | X3: Primer do UV | Y3: Termoformowanie-rolowa | Z3: Offset | AA3: LASER METAL | AB3: Wysokość profila | AC3: Szerokość profila | AD3: Materiał | AE3: Długość | AF3: Szerokość | AG3: indeks2
A4: POTF3W2BI | B4: Fala B dwust.bi 1200x600 | C4: gr. 430 | D4: m² | J4: DRUK SITO (folia, papier) [≠0,2] | K4: KASZEROWANY | L4: TEKTURA FAL. [3W, 5W] | N4: T. FALA [B] | Q4: Papier, Folia | R4: TEKTURA / PAPIER / FOLIA | AG4: =Tabela1[[#This Row],[Indeks]] -> POTF3W2BI
A5: POTF3W2BI | B5: Fala B jedn.bi | C5: gr. 430 | D5: m² | J5: DRUK SITO (folia, papier) [≠0,2] | K5: KASZEROWANY | L5: TEKTURA FAL. [3W, 5W] | N5: T. FALA [B] | Q5: Papier, Folia | R5: TEKTURA / PAPIER / FOLIA | AG5: =Tabela1[[#This Row],[Indeks]] -> POTF3W2BI
A6: POTF3WSZ | B6: Fala B szara | C6: gr. 422 | D6: m² | J6: DRUK SITO (folia, papier) [≠0,2] | K6: KASZEROWANY | L6: TEKTURA FAL. [3W, 5W] | N6: T. FALA [B] | Q6: Papier, Folia | R6: TEKTURA / PAPIER / FOLIA | AG6: =Tabela1[[#This Row],[Indeks]] -> POTF3WSZ
A7: POTF5WSZ-BC | B7: Fala BC | C7: gr.650 | D7: m² | J7: DRUK SITO (folia, papier) [≠0,2] | K7: KASZEROWANY | L7: TEKTURA FAL. [3W, 5W] | Q7: Papier, Folia | R7: TEKTURA / PAPIER / FOLIA | AG7: =Tabela1[[#This Row],[Indeks]] -> POTF5WSZ-BC
A8: POTF3W2BI | B8: Fala E dwust.bi | C8: gr. 400 | D8: m² | J8: DRUK SITO (folia, papier) [≠0,2] | K8: KASZEROWANY | L8: TEKTURA FAL. [3W, 5W] | N8: T. FALA [E] | Q8: Papier, Folia | R8: TEKTURA / PAPIER / FOLIA | AG8: =Tabela1[[#This Row],[Indeks]] -> POTF3W2BI
A9: POTF3WBI | B9: Fala E jedn.bi | C9: gr. 400 | D9: m² | J9: DRUK SITO (folia, papier) [≠0,2] | K9: KASZEROWANY | L9: TEKTURA FAL. [3W, 5W] | N9: T. FALA [E] | Q9: Papier, Folia | R9: TEKTURA / PAPIER / FOLIA | AG9: =Tabela1[[#This Row],[Indeks]] -> POTF3WBI
A10: POTF2WSZ | B10: Fala E szara | C10: gr. 383 | D10: m² | J10: DRUK SITO (folia, papier) [≠0,2] | K10: KASZEROWANY | L10: TEKTURA FAL. [3W, 5W] | N10: T. FALA [E] | Q10: Papier, Folia | R10: TEKTURA / PAPIER / FOLIA | AG10: =Tabela1[[#This Row],[Indeks]] -> POTF2WSZ
A11: POTF5W2BI-EB | B11: Fala EB dwust.bi | C11: gr.730 | D11: m² | J11: DRUK SITO (folia, papier) [≠0,2] | K11: KASZEROWANY | L11: TEKTURA FAL. [3W, 5W] | N11: T. FALA [EB] | Q11: Papier, Folia | R11: TEKTURA / PAPIER / FOLIA | AG11: =Tabela1[[#This Row],[Indeks]] -> POTF5W2BI-EB
A12: POTF5WBI-EB | B12: Fala EB jedn.bi | C12: gr.730 | D12: m² | J12: DRUK SITO (folia, papier) [≠0,2] | K12: KASZEROWANY | L12: TEKTURA FAL. [3W, 5W] | N12: T. FALA [EB] | Q12: Papier, Folia | R12: TEKTURA / PAPIER / FOLIA | AG12: =Tabela1[[#This Row],[Indeks]] -> POTF5WBI-EB
A13: POTF5WSZ-EB | B13: Fala EB szara | C13: gr.616 | D13: m² | J13: DRUK SITO (folia, papier) [≠0,2] | K13: KASZEROWANY | L13: TEKTURA FAL. [3W, 5W] | N13: T. FALA [EB] | Q13: Papier, Folia | R13: TEKTURA / PAPIER / FOLIA | AG13: =Tabela1[[#This Row],[Indeks]] -> POTF5WSZ-EB
A14: POTF5WSZ-BC | B14: Fala BC szara | C14: gr. 1010 | D14: m² | J14: DRUK SITO (folia, papier) [≠0,2] | K14: KASZEROWANY | L14: TEKTURA FAL. [3W, 5W] | Q14: Papier, Folia | R14: TEKTURA / PAPIER / FOLIA | AG14: =Tabela1[[#This Row],[Indeks]] -> POTF5WSZ-BC
A15: Folia AVERY 4500 translucent | B15: Folia AVERY 4500 translucent | D15: m² | Q15: Papier, Folia | AG15: =Tabela1[[#This Row],[Indeks]] -> Folia AVERY 4500 translucent
A16: Folia AVERY 500 biała i czarna ( ekonimiczna) | B16: Folia AVERY 500 biała i czarna ( ekonimiczna) | D16: m² | Q16: Papier, Folia | AG16: =Tabela1[[#This Row],[Indeks]] -> Folia AVERY 500 biała i czarna ( ekonimiczna)
A17: Folia AVERY 500 kolory ( ekonomiczna) | B17: Folia AVERY 500 kolory ( ekonomiczna) | D17: m² | Q17: Papier, Folia | AG17: =Tabela1[[#This Row],[Indeks]] -> Folia AVERY 500 kolory ( ekonomiczna)
A18: PŁVKBBF-1,0X0,7 | B18: Folia G-PET b/b p/p 1,0x700 | D18: kg | E18: VIVAK/PET/TUPET/AXPET | H18: Tupet, vivak, pcv | M18: PET | O18: VIVAK / PET itp. | P18: VIVAK / PET | S18: TUPET /PET / AXPET | T18: PET/VIVAK | U18: 1 | Y18: rolka | AG18: =Tabela1[[#This Row],[Indeks]] -> PŁVKBBF-1,0X0,7
A19: PODDFOBB-1,0X1,4 | B19: Folia sito b/b błysk 1000x1400 | D19: ark | I19: DRUK OFF SET [≠0,2] | J19: DRUK SITO (folia, papier) [≠0,2] | Q19: Papier, Folia | U19: 0.2 | AG19: =Tabela1[[#This Row],[Indeks]] -> PODDFOBB-1,0X1,4
A20: PODDFOBB-0,7X1,0 | B20: Folia sito b/b błysk 700x1000 | D20: ark | I20: DRUK OFF SET [≠0,2] | J20: DRUK SITO (folia, papier) [≠0,2] | Q20: Papier, Folia | U20: 0.2 | AG20: =Tabela1[[#This Row],[Indeks]] -> PODDFOBB-0,7X1,0
A21: PODDFOBP-1,0X1,4 | B21: Folia sito biała błysk 1000x1400 | D21: ark | I21: DRUK OFF SET [≠0,2] | J21: DRUK SITO (folia, papier) [≠0,2] | Q21: Papier, Folia | U21: 0.2 | AG21: =Tabela1[[#This Row],[Indeks]] -> PODDFOBP-1,0X1,4
A22: PODDFOBP-0,7X1,0 | B22: Folia sito biała błysk 700x1000 | D22: ark | I22: DRUK OFF SET [≠0,2] | J22: DRUK SITO (folia, papier) [≠0,2] | Q22: Papier, Folia | U22: 0.2 | AG22: =Tabela1[[#This Row],[Indeks]] -> PODDFOBP-0,7X1,0
A23: POMDFODD-1,05X50-P | B23: Folia solvent. Profiflex Pro poł 1,05x50 | D23: m² | F23: Papier, Folia | U23: 1 | AG23: =Tabela1[[#This Row],[Indeks]] -> POMDFODD-1,05X50-P
A24: POFODDTR-1,05X50 | B24: Folia transportowa 1,0x50 | D24: m² | U24: 1 | AG24: =Tabela1[[#This Row],[Indeks]] -> POFODDTR-1,05X50
